Workbook

Sheet Panduan
A1: PANDUAN SINGKAT
B3: Kos cowok & cewek | C3: Tab Uang Kos Mama: uang masuk tiap kamar (kos cowok 5 kamar, kos cewek 7 kamar), sumber masuk lain (lapak, penggantian), dan ke mana uang kos dipakai. Label kamar ada di tab Transaksi kolom L (Kos / Kamar).
B4: Struktur | C4: Setiap transaksi punya 3 tingkat: TUJUAN (Pendapatan / Pengeluaran / Pindah Uang) → SUMBER (Gaji, Jasa, Uang Kos Mama, Uang Kedai, Uang Disan / Pengeluaran Gaji, Jasa, Uang Kos, Uang Kedai, Uang Disan) → KATEGORI.
B5: Tabungan & investasi | C5: Tujuan "Tabungan": setor (beli saham/reksadana/jula-jula) dan cair. Di Dashboard dihitung sebagai bagian PENGELUARAN dalam bentuk "Tabungan bersih" (disetor − dicairkan), supaya uang yang diputar tidak terhitung berkali-kali. Dividen & bagi hasil = Pendapatan Gaji. Pembelian Reksadana Dana Kuliah = Pengeluaran Gaji › Pendidikan.
B6: Pindah Uang | C6: Tarik ATM, isi GoPay, pindah kantong, dana riba, utang-piutang → Tipe "Pindah" / Tujuan "Pindah Uang". Tidak dihitung pendapatan/pengeluaran.
B7: Mencatat | C7: Tab Transaksi, baris kosong paling bawah (mulai baris 16): Tanggal → Akun → Tipe → (Akun Tujuan kalau Pindah) → Jumlah → Tujuan → Sumber → Kategori → Keterangan.
B8: Mencari & melacak | C8: Tab Transaksi, panel kuning di atas: kata kunci, tujuan, sumber, kategori, akun, tipe, tanggal. Poin hasilnya muncul di kolom N–U (klik "Buka"); total masuk/keluar & per hari/bulan/tahun di tengah.
B9: Asal saldo akun | C9: Tab Saldo Akun bagian A: saldo awal + masuk − keluar + pindahan masuk − dipindah = saldo sekarang.
B10: Uang mama | C10: Tab Uang Mama: masuk (kos, kedai) − keluar (listrik kos, token & PDAM kedai, dll) = sisa uang mama. Sisa harus ada di Uang Kos Mama Cash / Kantong Uang Kos Mama; kalau belum, status "Pindahkan".
B11: Investasi | C11: Tab Investasi Saham & Investasi Reksadana: setiap beli/jual/dividen ada tautan "Kas" ke transaksinya, dari pengeluaran apa/akun apa, dan dana yang masuk sebelumnya.
B12: Perencanaan | C12: Target Dana Darurat, Kuliah, Laptop terhubung ke nilai reksadana per tujuan. Isi tenggat untuk melihat tabungan per bulan yang dibutuhkan.
B13: Perlu Dicek | C13: Transaksi bertanda kuning di kolom K perlu kamu pastikan. Cari dengan panel: "Hanya Perlu Dicek" = Ya.
B14: Uang Riba | C14: Tab Uang Riba: riba masuk, pajak, selisih bunga, uang riba yang dipinjam & diganti, dan sisa utang ke uang riba per bulan. Pinjam = kategori "Pinjam dari uang riba", ganti = "Ganti uang riba" (Tujuan Pindah Uang › Sumber Pinjam uang riba).
... B18: Buku Akun | C18: Tab Buku Akun: pilih akun, bulan & tahun → transaksi akun itu urut per tanggal dengan saldo setelah tiap transaksi, total masuk/keluar, dan saldo akhir bulan (seperti buku bank).

Sheet Dashboard
A1: DASHBOARD
A2: Pilih Tahun dan Bulan di sel kuning. Untuk melacak angka mana pun: buka tab Transaksi, lalu isi Tujuan/Sumber/Kategori/Akun dan tanggal di panel pencarian — poin transaksinya muncul di kanan.
B4: Tahun | C4: 2026 | D4: =MATCH(C5,Ref!$A$1:$A$12,0)
B5: Bulan | C5: September
B7: ="A. PENDAPATAN & PENGELUARAN — "&UPPER(C5)&" "&C4
B8: Sumber | C8: Bulan ini | D8: Tahun ini | E8: Rata-rata/bulan (tahun ini) | F8: Porsi (tahun)
B9: PENDAPATAN
B10: Gaji | C10: =SUMIFS(Transaksi!$F$16:$F$5015,Transaksi!$G$16:$G$5015,"Pendapatan",Transaksi!$B$16:$B$5015,">="&DATE(Dashboard!$C$4,Dashboard!$D$4,1),Transaksi!$B$16:$B$5015,"<="&EOMONTH(DATE(Dashboard!$C$4,Dashboard!$D$4,1),0),Transaksi!$H$16:$H$5015,"Gaji") | D10: =SUMIFS(Transaksi!$F$16:$F$5015,Transaksi!$G$16:$G$5015,"Pendapatan",Transaksi!$B$16:$B$5015,">="&DATE(Dashboard!$C$4,1,1),Transaksi!$B$16:$B$5015,"<="&DATE(Dashboard!$C$4,12,31),Transaksi!$H$16:$H$5015,"Gaji") | E10: =D10/MAX(1,IF(Dashboard!$C$4=YEAR(TODAY()),MONTH(TODAY()),12)) | F10: =IF(SUM($D$10:$D$14)=0,"-",D10/SUM($D$10:$D$14))
B11: Jasa | C11: =SUMIFS(Transaksi!$F$16:$F$5015,Transaksi!$G$16:$G$5015,"Pendapatan",Transaksi!$B$16:$B$5015,">="&DATE(Dashboard!$C$4,Dashboard!$D$4,1),Transaksi!$B$16:$B$5015,"<="&EOMONTH(DATE(Dashboard!$C$4,Dashboard!$D$4,1),0),Transaksi!$H$16:$H$5015,"Jasa") | D11: =SUMIFS(Transaksi!$F$16:$F$5015,Transaksi!$G$16:$G$5015,"Pendapatan",Transaksi!$B$16:$B$5015,">="&DATE(Dashboard!$C$4,1,1),Transaksi!$B$16:$B$5015,"<="&DATE(Dashboard!$C$4,12,31),Transaksi!$H$16:$H$5015,"Jasa") | E11: =D11/MAX(1,IF(Dashboard!$C$4=YEAR(TODAY()),MONTH(TODAY()),12)) | F11: =IF(SUM($D$10:$D$14)=0,"-",D11/SUM($D$10:$D$14))
B12: Uang Kos Mama | C12: =SUMIFS(Transaksi!$F$16:$F$5015,Transaksi!$G$16:$G$5015,"Pendapatan",Transaksi!$B$16:$B$5015,">="&DATE(Dashboard!$C$4,Dashboard!$D$4,1),Transaksi!$B$16:$B$5015,"<="&EOMONTH(DATE(Dashboard!$C$4,Dashboard!$D$4,1),0),Transaksi!$H$16:$H$5015,"Uang Kos Mama") | D12: =SUMIFS(Transaksi!$F$16:$F$5015,Transaksi!$G$16:$G$5015,"Pendapatan",Transaksi!$B$16:$B$5015,">="&DATE(Dashboard!$C$4,1,1),Transaksi!$B$16:$B$5015,"<="&DATE(Dashboard!$C$4,12,31),Transaksi!$H$16:$H$5015,"Uang Kos Mama") | E12: =D12/MAX(1,IF(Dashboard!$C$4=YEAR(TODAY()),MONTH(TODAY()),12)) | F12: =IF(SUM($D$10:$D$14)=0,"-",D12/SUM($D$10:$D$14))
B13: Uang Kedai | C13: =SUMIFS(Transaksi!$F$16:$F$5015,Transaksi!$G$16:$G$5015,"Pendapatan",Transaksi!$B$16:$B$5015,">="&DATE(Dashboard!$C$4,Dashboard!$D$4,1),Transaksi!$B$16:$B$5015,"<="&EOMONTH(DATE(Dashboard!$C$4,Dashboard!$D$4,1),0),Transaksi!$H$16:$H$5015,"Uang Kedai") | D13: =SUMIFS(Transaksi!$F$16:$F$5015,Transaksi!$G$16:$G$5015,"Pendapatan",Transaksi!$B$16:$B$5015,">="&DATE(Dashboard!$C$4,1,1),Transaksi!$B$16:$B$5015,"<="&DATE(Dashboard!$C$4,12,31),Transaksi!$H$16:$H$5015,"Uang Kedai") | E13: =D13/MAX(1,IF(Dashboard!$C$4=YEAR(TODAY()),MONTH(TODAY()),12)) | F13: =IF(SUM($D$10:$D$14)=0,"-",D13/SUM($D$10:$D$14))
B14: Uang Disan | C14: =SUMIFS(Transaksi!$F$16:$F$5015,Transaksi!$G$16:$G$5015,"Pendapatan",Transaksi!$B$16:$B$5015,">="&DATE(Dashboard!$C$4,Dashboard!$D$4,1),Transaksi!$B$16:$B$5015,"<="&EOMONTH(DATE(Dashboard!$C$4,Dashboard!$D$4,1),0),Transaksi!$H$16:$H$5015,"Uang Disan") | D14: =SUMIFS(Transaksi!$F$16:$F$5015,Transaksi!$G$16:$G$5015,"Pendapatan",Transaksi!$B$16:$B$5015,">="&DATE(Dashboard!$C$4,1,1),Transaksi!$B$16:$B$5015,"<="&DATE(Dashboard!$C$4,12,31),Transaksi!$H$16:$H$5015,"Uang Disan") | E14: =D14/MAX(1,IF(Dashboard!$C$4=YEAR(TODAY()),MONTH(TODAY()),12)) | F14: =IF(SUM($D$10:$D$14)=0,"-",D14/SUM($D$10:$D$14))
B15: Total pendapatan | C15: =SUM(C10:C14) | D15: =SUM(D10:D14) | E15: =SUM(E10:E14)
B17: PENGELUARAN
B18: Pengeluaran Gaji | C18: =SUMIFS(Transaksi!$F$16:$F$5015,Transaksi!$G$16:$G$5015,"Pengeluaran",Transaksi!$B$16:$B$5015,">="&DATE(Dashboard!$C$4,Dashboard!$D$4,1),Transaksi!$B$16:$B$5015,"<="&EOMONTH(DATE(Dashboard!$C$4,Dashboard!$D$4,1),0),Transaksi!$H$16:$H$5015,"Pengeluaran Gaji") | D18: =SUMIFS(Transaksi!$F$16:$F$5015,Transaksi!$G$16:$G$5015,"Pengeluaran",Transaksi!$B$16:$B$5015,">="&DATE(Dashboard!$C$4,1,1),Transaksi!$B$16:$B$5015,"<="&DATE(Dashboard!$C$4,12,31),Transaksi!$H$16:$H$5015,"Pengeluaran Gaji") | E18: =D18/MAX(1,IF(Dashboard!$C$4=YEAR(TODAY()),MONTH(TODAY()),12)) | F18: =IF(SUM($D$18:$D$22)=0,"-",D18/SUM($D$18:$D$22))
B19: Pengeluaran Jasa | C19: =SUMIFS(Transaksi!$F$16:$F$5015,Transaksi!$G$16:$G$5015,"Pengeluaran",Transaksi!$B$16:$B$5015,">="&DATE(Dashboard!$C$4,Dashboard!$D$4,1),Transaksi!$B$16:$B$5015,"<="&EOMONTH(DATE(Dashboard!$C$4,Dashboard!$D$4,1),0),Transaksi!$H$16:$H$5015,"Pengeluaran Jasa") | D19: =SUMIFS(Transaksi!$F$16:$F$5015,Transaksi!$G$16:$G$5015,"Pengeluaran",Transaksi!$B$16:$B$5015,">="&DATE(Dashboard!$C$4,1,1),Transaksi!$B$16:$B$5015,"<="&DATE(Dashboard!$C$4,12,31),Transaksi!$H$16:$H$5015,"Pengeluaran Jasa") | E19: =D19/MAX(1,IF(Dashboard!$C$4=YEAR(TODAY()),MONTH(TODAY()),12)) | F19: =IF(SUM($D$18:$D$22)=0,"-",D19/SUM($D$18:$D$22))
B20: Pengeluaran Uang Kos | C20: =SUMIFS(Transaksi!$F$16:$F$5015,Transaksi!$G$16:$G$5015,"Pengeluaran",Transaksi!$B$16:$B$5015,">="&DATE(Dashboard!$C$4,Dashboard!$D$4,1),Transaksi!$B$16:$B$5015,"<="&EOMONTH(DATE(Dashboard!$C$4,Dashboard!$D$4,1),0),Transaksi!$H$16:$H$5015,"Pengeluaran Uang Kos") | D20: =SUMIFS(Transaksi!$F$16:$F$5015,Transaksi!$G$16:$G$5015,"Pengeluaran",Transaksi!$B$16:$B$5015,">="&DATE(Dashboard!$C$4,1,1),Transaksi!$B$16:$B$5015,"<="&DATE(Dashboard!$C$4,12,31),Transaksi!$H$16:$H$5015,"Pengeluaran Uang Kos") | E20: =D20/MAX(1,IF(Dashboard!$C$4=YEAR(TODAY()),MONTH(TODAY()),12)) | F20: =IF(SUM($D$18:$D$22)=0,"-",D20/SUM($D$18:$D$22))
B21: Pengeluaran Uang Kedai | C21: =SUMIFS(Transaksi!$F$16:$F$5015,Transaksi!$G$16:$G$5015,"Pengeluaran",Transaksi!$B$16:$B$5015,">="&DATE(Dashboard!$C$4,Dashboard!$D$4,1),Transaksi!$B$16:$B$5015,"<="&EOMONTH(DATE(Dashboard!$C$4,Dashboard!$D$4,1),0),Transaksi!$H$16:$H$5015,"Pengeluaran Uang Kedai") | D21: =SUMIFS(Transaksi!$F$16:$F$5015,Transaksi!$G$16:$G$5015,"Pengeluaran",Transaksi!$B$16:$B$5015,">="&DATE(Dashboard!$C$4,1,1),Transaksi!$B$16:$B$5015,"<="&DATE(Dashboard!$C$4,12,31),Transaksi!$H$16:$H$5015,"Pengeluaran Uang Kedai") | E21: =D21/MAX(1,IF(Dashboard!$C$4=YEAR(TODAY()),MONTH(TODAY()),12)) | F21: =IF(SUM($D$18:$D$22)=0,"-",D21/SUM($D$18:$D$22))
B22: Pengeluaran Uang Disan | C22: =SUMIFS(Transaksi!$F$16:$F$5015,Transaksi!$G$16:$G$5015,"Pengeluaran",Transaksi!$B$16:$B$5015,">="&DATE(Dashboard!$C$4,Dashboard!$D$4,1),Transaksi!$B$16:$B$5015,"<="&EOMONTH(DATE(Dashboard!$C$4,Dashboard!$D$4,1),0),Transaksi!$H$16:$H$5015,"Pengeluaran Uang Disan") | D22: =SUMIFS(Transaksi!$F$16:$F$5015,Transaksi!$G$16:$G$5015,"Pengeluaran",Transaksi!$B$16:$B$5015,">="&DATE(Dashboard!$C$4,1,1),Transaksi!$B$16:$B$5015,"<="&DATE(Dashboard!$C$4,12,31),Transaksi!$H$16:$H$5015,"Pengeluaran Uang Disan") | E22: =D22/MAX(1,IF(Dashboard!$C$4=YEAR(TODAY()),MONTH(TODAY()),12)) | F22: =IF(SUM($D$18:$D$22)=0,"-",D22/SUM($D$18:$D$22))
B23: Tabungan bersih (disetor − dicairkan) | C23: =(SUMIFS(Transaksi!$F$16:$F$5015,Transaksi!$G$16:$G$5015,"Tabungan",Transaksi!$D$16:$D$5015,"Keluar",Transaksi!$H$16:$H$5015,"<>Reksadana uang kos mama",Transaksi!$B$16:$B$5015,">="&DATE(Dashboard!$C$4,Dashboard!$D$4,1),Transaksi!$B$16:$B$5015,"<="&EOMONTH(DATE(Dashboard!$C$4,Dashboard!$D$4,1),0))-SUMIFS(Transaksi!$F$16:$F$5015,Transaksi!$G$16:$G$5015,"Tabungan",Transaksi!$D$16:$D$5015,"Masuk",Transaksi!$H$16:$H$5015,"<>Reksadana uang kos mama",Transaksi!$B$16:$B$5015,">="&DATE(Dashboard!$C$4,Dashboard!$D$4,1),Transaksi!$B$16:$B$5015,"<="&EOMONTH(DATE(Dashboard!$C$4,Dashboard!$D$4,1),0))) | D23: =(SUMIFS(Transaksi!$F$16:$F$5015,Transaksi!$G$16:$G$5015,"Tabungan",Transaksi!$D$16:$D$5015,"Keluar",Transaksi!$H$16:$H$5015,"<>Reksadana uang kos mama",Transaksi!$B$16:$B$5015,">="&DATE(Dashboard!$C$4,1,1),Transaksi!$B$16:$B$5015,"<="&DATE(Dashboard!$C$4,12,31))-SUMIFS(Transaksi!$F$16:$F$5015,Transaksi!$G$16:$G$5015,"Tabungan",Transaksi!$D$16:$D$5015,"Masuk",Transaksi!$H$16:$H$5015,"<>Reksadana uang kos mama",Transaksi!$B$16:$B$5015,">="&DATE(Dashboard!$C$4,1,1),Transaksi!$B$16:$B$5015,"<="&DATE(Dashboard!$C$4,12,31))) | E23: =D23/MAX(1,IF(Dashboard!$C$4=YEAR(TODAY()),MONTH(TODAY()),12)) | F23: =IF(SUM($D$18:$D$23)=0,"-",D23/SUM($D$18:$D$23))
B24: Total pengeluaran | C24: =SUM(C18:C23) | D24: =SUM(D18:D23) | E24: =SUM(E18:E23)
B26: SELISIH (pendapatan − pengeluaran) | C26: =C15-C24 | D26: =D15-D24 | E26: =E15-E24
B28: ="B. PER BULAN — TAHUN "&C4
B29: Bulan | C29: Pendapatan | D29: Pengeluaran | E29: Ditabung (bersih) | F29: Selisih | G29: Uang mama bulan ini (masuk − keluar) | H29: Saldo semua akun (akhir bulan)
B30: Januari | C30: =SUMIFS(Transaksi!$F$16:$F$5015,Transaksi!$G$16:$G$5015,"Pendapatan",Transaksi!$B$16:$B$5015,">="&DATE(Dashboard!$C$4,1,1),Transaksi!$B$16:$B$5015,"<="&EOMONTH(DATE(Dashboard!$C$4,1,1),0)) | D30: =SUMIFS(Transaksi!$F$16:$F$5015,Transaksi!$G$16:$G$5015,"Pengeluaran",Transaksi!$B$16:$B$5015,">="&DATE(Dashboard!$C$4,1,1),Transaksi!$B$16:$B$5015,"<="&EOMONTH(DATE(Dashboard!$C$4,1,1),0)) | E30: =(SUMIFS(Transaksi!$F$16:$F$5015,Transaksi!$G$16:$G$5015,"Tabungan",Transaksi!$D$16:$D$5015,"Keluar",Transaksi!$H$16:$H$5015,"<>Reksadana uang kos mama",Transaksi!$B$16:$B$5015,">="&DATE(Dashboard!$C$4,1,1),Transaksi!$B$16:$B$5015,"<="&EOMONTH(DATE(Dashboard!$C$4,1,1),0))-SUMIFS(Transaksi!$F$16:$F$5015,Transaksi!$G$16:$G$5015,"Tabungan",Transaksi!$D$16:$D$5015,"Masuk",Transaksi!$H$16:$H$5015,"<>Reksadana uang kos mama",Transaksi!$B$16:$B$5015,">="&DATE(Dashboard!$C$4,1,1),Transaksi!$B$16:$B$5015,"<="&EOMONTH(DATE(Dashboard!$C$4,1,1),0))) | F30: =C30-D30-E30 | G30: =SUMIFS(Transaksi!$F$16:$F$5015,Transaksi!$G$16:$G$5015,"Pendapatan",Transaksi!$B$16:$B$5015,">="&DATE(Dashboard!$C$4,1,1),Transaksi!$B$16:$B$5015,"<="&EOMONTH(DATE(Dashboard!$C$4,1,1),0),Transaksi!$H$16:$H$5015,"Uang Kos Mama")+SUMIFS(Transaksi!$F$16:$F$5015,Transaksi!$G$16:$G$5015,"Pendapatan",Transaksi!$B$16:$B$5015,">="&DATE(Dashboard!$C$4,1,1),Transaksi!$B$16:$B$5015,"<="&EOMONTH(DATE(Dashboard!$C$4,1,1),0),Transaksi!$H$16:$H$5015,"Uang Kedai")-SUMIFS(Transaksi!$F$16:$F$5015,Transaksi!$G$16:$G$5015,"Pengeluaran",Transaksi!$B$16:$B$5015,">="&DATE(Dashboard!$C$4,1,1),Transaksi!$B$16:$B$5015,"<="&EOMONTH(DATE(Dashboard!$C$4,1,1),0),Transaksi!$H$16:$H$5015,"Pengeluaran Uang Kos")-SUMIFS(Transaksi!$F$16:$F$5015,Transaksi!$G$16:$G$5015,"Pengeluaran",Transaksi!$B$16:$B$5015,">="&DATE(Dashboard!$C$4,1,1),Transaksi!$B$16:$B$5015,"<="&EOMONTH(DATE(Dashboard!$C$4,1,1),0),Transaksi!$H$16:$H$5015,"Pengeluaran Uang Kedai")-(SUMIFS(Transaksi!$F$16:$F$5015,Transaksi!$G$16:$G$5015,"Tabungan",Transaksi!$D$16:$D$5015,"Keluar",Transaksi!$H$16:$H$5015,"Reksadana uang kos mama",Transaksi!$B$16:$B$5015,">="&DATE(Dashboard!$C$4,1,1),Transaksi!$B$16:$B$5015,"<="&EOMONTH(DATE(Dashboard!$C$4,1,1),0))-SUMIFS(Transaksi!$F$16:$F$5015,Transaksi!$G$16:$G$5015,"Tabungan",Transaksi!$D$16:$D$5015,"Masuk",Transaksi!$H$16:$H$5015,"Reksadana uang kos mama",Transaksi!$B$16:$B$5015,">="&DATE(Dashboard!$C$4,1,1),Transaksi!$B$16:$B$5015,"<="&EOMONTH(DATE(Dashboard!$C$4,1,1),0))) | H30: =IF(DATE(Dashboard!$C$4,1,1)>TODAY(),"",SUMPRODUCT((Akun!$A$5:$A$104<>"")*1,Akun!$C$5:$C$104,--(Akun!$D$5:$D$104<=EOMONTH(DATE(Dashboard!$C$4,1,1),0)))+SUMIFS(Transaksi!$F$16:$F$5015,Transaksi!$D$16:$D$5015,"Masuk",Transaksi!$B$16:$B$5015,"<="&EOMONTH(DATE(Dashboard!$C$4,1,1),0))-SUMIFS(Transaksi!$F$16:$F$5015,Transaksi!$D$16:$D$5015,"Keluar",Transaksi!$B$16:$B$5015,"<="&EOMONTH(DATE(Dashboard!$C$4,1,1),0)))
B31: Februari | C31: =SUMIFS(Transaksi!$F$16:$F$5015,Transaksi!$G$16:$G$5015,"Pendapatan",Transaksi!$B$16:$B$5015,">="&DATE(Dashboard!$C$4,2,1),Transaksi!$B$16:$B$5015,"<="&EOMONTH(DATE(Dashboard!$C$4,2,1),0)) | D31: =SUMIFS(Transaksi!$F$16:$F$5015,Transaksi!$G$16:$G$5015,"Pengeluaran",Transaksi!$B$16:$B$5015,">="&DATE(Dashboard!$C$4,2,1),Transaksi!$B$16:$B$5015,"<="&EOMONTH(DATE(Dashboard!$C$4,2,1),0)) | E31: =(SUMIFS(Transaksi!$F$16:$F$5015,Transaksi!$G$16:$G$5015,"Tabungan",Transaksi!$D$16:$D$5015,"Keluar",Transaksi!$H$16:$H$5015,"<>Reksadana uang kos mama",Transaksi!$B$16:$B$5015,">="&DATE(Dashboard!$C$4,2,1),Transaksi!$B$16:$B$5015,"<="&EOMONTH(DATE(Dashboard!$C$4,2,1),0))-SUMIFS(Transaksi!$F$16:$F$5015,Transaksi!$G$16:$G$5015,"Tabungan",Transaksi!$D$16:$D$5015,"Masuk",Transaksi!$H$16:$H$5015,"<>Reksadana uang kos mama",Transaksi!$B$16:$B$5015,">="&DATE(Dashboard!$C$4,2,1),Transaksi!$B$16:$B$5015,"<="&EOMONTH(DATE(Dashboard!$C$4,2,1),0))) | F31: =C31-D31-E31 | G31: =SUMIFS(Transaksi!$F$16:$F$5015,Transaksi!$G$16:$G$5015,"Pendapatan",Transaksi!$B$16:$B$5015,">="&DATE(Dashboard!$C$4,2,1),Transaksi!$B$16:$B$5015,"<="&EOMONTH(DATE(Dashboard!$C$4,2,1),0),Transaksi!$H$16:$H$5015,"Uang Kos Mama")+SUMIFS(Transaksi!$F$16:$F$5015,Transaksi!$G$16:$G$5015,"Pendapatan",Transaksi!$B$16:$B$5015,">="&DATE(Dashboard!$C$4,2,1),Transaksi!$B$16:$B$5015,"<="&EOMONTH(DATE(Dashboard!$C$4,2,1),0),Transaksi!$H$16:$H$5015,"Uang Kedai")-SUMIFS(Transaksi!$F$16:$F$5015,Transaksi!$G$16:$G$5015,"Pengeluaran",Transaksi!$B$16:$B$5015,">="&DATE(Dashboard!$C$4,2,1),Transaksi!$B$16:$B$5015,"<="&EOMONTH(DATE(Dashboard!$C$4,2,1),0),Transaksi!$H$16:$H$5015,"Pengeluaran Uang Kos")-SUMIFS(Transaksi!$F$16:$F$5015,Transaksi!$G$16:$G$5015,"Pengeluaran",Transaksi!$B$16:$B$5015,">="&DATE(Dashboard!$C$4,2,1),Transaksi!$B$16:$B$5015,"<="&EOMONTH(DATE(Dashboard!$C$4,2,1),0),Transaksi!$H$16:$H$5015,"Pengeluaran Uang Kedai")-(SUMIFS(Transaksi!$F$16:$F$5015,Transaksi!$G$16:$G$5015,"Tabungan",Transaksi!$D$16:$D$5015,"Keluar",Transaksi!$H$16:$H$5015,"Reksadana uang kos mama",Transaksi!$B$16:$B$5015,">="&DATE(Dashboard!$C$4,2,1),Transaksi!$B$16:$B$5015,"<="&EOMONTH(DATE(Dashboard!$C$4,2,1),0))-SUMIFS(Transaksi!$F$16:$F$5015,Transaksi!$G$16:$G$5015,"Tabungan",Transaksi!$D$16:$D$5015,"Masuk",Transaksi!$H$16:$H$5015,"Reksadana uang kos mama",Transaksi!$B$16:$B$5015,">="&DATE(Dashboard!$C$4,2,1),Transaksi!$B$16:$B$5015,"<="&EOMONTH(DATE(Dashboard!$C$4,2,1),0))) | H31: =IF(DATE(Dashboard!$C$4,2,1)>TODAY(),"",SUMPRODUCT((Akun!$A$5:$A$104<>"")*1,Akun!$C$5:$C$104,--(Akun!$D$5:$D$104<=EOMONTH(DATE(Dashboard!$C$4,2,1),0)))+SUMIFS(Transaksi!$F$16:$F$5015,Transaksi!$D$16:$D$5015,"Masuk",Transaksi!$B$16:$B$5015,"<="&EOMONTH(DATE(Dashboard!$C$4,2,1),0))-SUMIFS(Transaksi!$F$16:$F$5015,Transaksi!$D$16:$D$5015,"Keluar",Transaksi!$B$16:$B$5015,"<="&EOMONTH(DATE(Dashboard!$C$4,2,1),0)))
B32: Maret | C32: =SUMIFS(Transaksi!$F$16:$F$5015,Transaksi!$G$16:$G$5015,"Pendapatan",Transaksi!$B$16:$B$5015,">="&DATE(Dashboard!$C$4,3,1),Transaksi!$B$16:$B$5015,"<="&EOMONTH(DATE(Dashboard!$C$4,3,1),0)) | D32: =SUMIFS(Transaksi!$F$16:$F$5015,Transaksi!$G$16:$G$5015,"Pengeluaran",Transaksi!$B$16:$B$5015,">="&DATE(Dashboard!$C$4,3,1),Transaksi!$B$16:$B$5015,"<="&EOMONTH(DATE(Dashboard!$C$4,3,1),0)) | E32: =(SUMIFS(Transaksi!$F$16:$F$5015,Transaksi!$G$16:$G$5015,"Tabungan",Transaksi!$D$16:$D$5015,"Keluar",Transaksi!$H$16:$H$5015,"<>Reksadana uang kos mama",Transaksi!$B$16:$B$5015,">="&DATE(Dashboard!$C$4,3,1),Transaksi!$B$16:$B$5015,"<="&EOMONTH(DATE(Dashboard!$C$4,3,1),0))-SUMIFS(Transaksi!$F$16:$F$5015,Transaksi!$G$16:$G$5015,"Tabungan",Transaksi!$D$16:$D$5015,"Masuk",Transaksi!$H$16:$H$5015,"<>Reksadana uang kos mama",Transaksi!$B$16:$B$5015,">="&DATE(Dashboard!$C$4,3,1),Transaksi!$B$16:$B$5015,"<="&EOMONTH(DATE(Dashboard!$C$4,3,1),0))) | F32: =C32-D32-E32 | G32: =SUMIFS(Transaksi!$F$16:$F$5015,Transaksi!$G$16:$G$5015,"Pendapatan",Transaksi!$B$16:$B$5015,">="&DATE(Dashboard!$C$4,3,1),Transaksi!$B$16:$B$5015,"<="&EOMONTH(DATE(Dashboard!$C$4,3,1),0),Transaksi!$H$16:$H$5015,"Uang Kos Mama")+SUMIFS(Transaksi!$F$16:$F$5015,Transaksi!$G$16:$G$5015,"Pendapatan",Transaksi!$B$16:$B$5015,">="&DATE(Dashboard!$C$4,3,1),Transaksi!$B$16:$B$5015,"<="&EOMONTH(DATE(Dashboard!$C$4,3,1),0),Transaksi!$H$16:$H$5015,"Uang Kedai")-SUMIFS(Transaksi!$F$16:$F$5015,Transaksi!$G$16:$G$5015,"Pengeluaran",Transaksi!$B$16:$B$5015,">="&DATE(Dashboard!$C$4,3,1),Transaksi!$B$16:$B$5015,"<="&EOMONTH(DATE(Dashboard!$C$4,3,1),0),Transaksi!$H$16:$H$5015,"Pengeluaran Uang Kos")-SUMIFS(Transaksi!$F$16:$F$5015,Transaksi!$G$16:$G$5015,"Pengeluaran",Transaksi!$B$16:$B$5015,">="&DATE(Dashboard!$C$4,3,1),Transaksi!$B$16:$B$5015,"<="&EOMONTH(DATE(Dashboard!$C$4,3,1),0),Transaksi!$H$16:$H$5015,"Pengeluaran Uang Kedai")-(SUMIFS(Transaksi!$F$16:$F$5015,Transaksi!$G$16:$G$5015,"Tabungan",Transaksi!$D$16:$D$5015,"Keluar",Transaksi!$H$16:$H$5015,"Reksadana uang kos mama",Transaksi!$B$16:$B$5015,">="&DATE(Dashboard!$C$4,3,1),Transaksi!$B$16:$B$5015,"<="&EOMONTH(DATE(Dashboard!$C$4,3,1),0))-SUMIFS(Transaksi!$F$16:$F$5015,Transaksi!$G$16:$G$5015,"Tabungan",Transaksi!$D$16:$D$5015,"Masuk",Transaksi!$H$16:$H$5015,"Reksadana uang kos mama",Transaksi!$B$16:$B$5015,">="&DATE(Dashboard!$C$4,3,1),Transaksi!$B$16:$B$5015,"<="&EOMONTH(DATE(Dashboard!$C$4,3,1),0))) | H32: =IF(DATE(Dashboard!$C$4,3,1)>TODAY(),"",SUMPRODUCT((Akun!$A$5:$A$104<>"")*1,Akun!$C$5:$C$104,--(Akun!$D$5:$D$104<=EOMONTH(DATE(Dashboard!$C$4,3,1),0)))+SUMIFS(Transaksi!$F$16:$F$5015,Transaksi!$D$16:$D$5015,"Masuk",Transaksi!$B$16:$B$5015,"<="&EOMONTH(DATE(Dashboard!$C$4,3,1),0))-SUMIFS(Transaksi!$F$16:$F$5015,Transaksi!$D$16:$D$5015,"Keluar",Transaksi!$B$16:$B$5015,"<="&EOMONTH(DATE(Dashboard!$C$4,3,1),0)))
B33: April | C33: =SUMIFS(Transaksi!$F$16:$F$5015,Transaksi!$G$16:$G$5015,"Pendapatan",Transaksi!$B$16:$B$5015,">="&DATE(Dashboard!$C$4,4,1),Transaksi!$B$16:$B$5015,"<="&EOMONTH(DATE(Dashboard!$C$4,4,1),0)) | D33: =SUMIFS(Transaksi!$F$16:$F$5015,Transaksi!$G$16:$G$5015,"Pengeluaran",Transaksi!$B$16:$B$5015,">="&DATE(Dashboard!$C$4,4,1),Transaksi!$B$16:$B$5015,"<="&EOMONTH(DATE(Dashboard!$C$4,4,1),0)) | E33: =(SUMIFS(Transaksi!$F$16:$F$5015,Transaksi!$G$16:$G$5015,"Tabungan",Transaksi!$D$16:$D$5015,"Keluar",Transaksi!$H$16:$H$5015,"<>Reksadana uang kos mama",Transaksi!$B$16:$B$5015,">="&DATE(Dashboard!$C$4,4,1),Transaksi!$B$16:$B$5015,"<="&EOMONTH(DATE(Dashboard!$C$4,4,1),0))-SUMIFS(Transaksi!$F$16:$F$5015,Transaksi!$G$16:$G$5015,"Tabungan",Transaksi!$D$16:$D$5015,"Masuk",Transaksi!$H$16:$H$5015,"<>Reksadana uang kos mama",Transaksi!$B$16:$B$5015,">="&DATE(Dashboard!$C$4,4,1),Transaksi!$B$16:$B$5015,"<="&EOMONTH(DATE(Dashboard!$C$4,4,1),0))) | F33: =C33-D33-E33 | G33: =SUMIFS(Transaksi!$F$16:$F$5015,Transaksi!$G$16:$G$5015,"Pendapatan",Transaksi!$B$16:$B$5015,">="&DATE(Dashboard!$C$4,4,1),Transaksi!$B$16:$B$5015,"<="&EOMONTH(DATE(Dashboard!$C$4,4,1),0),Transaksi!$H$16:$H$5015,"Uang Kos Mama")+SUMIFS(Transaksi!$F$16:$F$5015,Transaksi!$G$16:$G$5015,"Pendapatan",Transaksi!$B$16:$B$5015,">="&DATE(Dashboard!$C$4,4,1),Transaksi!$B$16:$B$5015,"<="&EOMONTH(DATE(Dashboard!$C$4,4,1),0),Transaksi!$H$16:$H$5015,"Uang Kedai")-SUMIFS(Transaksi!$F$16:$F$5015,Transaksi!$G$16:$G$5015,"Pengeluaran",Transaksi!$B$16:$B$5015,">="&DATE(Dashboard!$C$4,4,1),Transaksi!$B$16:$B$5015,"<="&EOMONTH(DATE(Dashboard!$C$4,4,1),0),Transaksi!$H$16:$H$5015,"Pengeluaran Uang Kos")-SUMIFS(Transaksi!$F$16:$F$5015,Transaksi!$G$16:$G$5015,"Pengeluaran",Transaksi!$B$16:$B$5015,">="&DATE(Dashboard!$C$4,4,1),Transaksi!$B$16:$B$5015,"<="&EOMONTH(DATE(Dashboard!$C$4,4,1),0),Transaksi!$H$16:$H$5015,"Pengeluaran Uang Kedai")-(SUMIFS(Transaksi!$F$16:$F$5015,Transaksi!$G$16:$G$5015,"Tabungan",Transaksi!$D$16:$D$5015,"Keluar",Transaksi!$H$16:$H$5015,"Reksadana uang kos mama",Transaksi!$B$16:$B$5015,">="&DATE(Dashboard!$C$4,4,1),Transaksi!$B$16:$B$5015,"<="&EOMONTH(DATE(Dashboard!$C$4,4,1),0))-SUMIFS(Transaksi!$F$16:$F$5015,Transaksi!$G$16:$G$5015,"Tabungan",Transaksi!$D$16:$D$5015,"Masuk",Transaksi!$H$16:$H$5015,"Reksadana uang kos mama",Transaksi!$B$16:$B$5015,">="&DATE(Dashboard!$C$4,4,1),Transaksi!$B$16:$B$5015,"<="&EOMONTH(DATE(Dashboard!$C$4,4,1),0))) | H33: =IF(DATE(Dashboard!$C$4,4,1)>TODAY(),"",SUMPRODUCT((Akun!$A$5:$A$104<>"")*1,Akun!$C$5:$C$104,--(Akun!$D$5:$D$104<=EOMONTH(DATE(Dashboard!$C$4,4,1),0)))+SUMIFS(Transaksi!$F$16:$F$5015,Transaksi!$D$16:$D$5015,"Masuk",Transaksi!$B$16:$B$5015,"<="&EOMONTH(DATE(Dashboard!$C$4,4,1),0))-SUMIFS(Transaksi!$F$16:$F$5015,Transaksi!$D$16:$D$5015,"Keluar",Transaksi!$B$16:$B$5015,"<="&EOMONTH(DATE(Dashboard!$C$4,4,1),0)))
B34: Mei | C34: =SUMIFS(Transaksi!$F$16:$F$5015,Transaksi!$G$16:$G$5015,"Pendapatan",Transaksi!$B$16:$B$5015,">="&DATE(Dashboard!$C$4,5,1),Transaksi!$B$16:$B$5015,"<="&EOMONTH(DATE(Dashboard!$C$4,5,1),0)) | D34: =SUMIFS(Transaksi!$F$16:$F$5015,Transaksi!$G$16:$G$5015,"Pengeluaran",Transaksi!$B$16:$B$5015,">="&DATE(Dashboard!$C$4,5,1),Transaksi!$B$16:$B$5015,"<="&EOMONTH(DATE(Dashboard!$C$4,5,1),0)) | E34: =(SUMIFS(Transaksi!$F$16:$F$5015,Transaksi!$G$16:$G$5015,"Tabungan",Transaksi!$D$16:$D$5015,"Keluar",Transaksi!$H$16:$H$5015,"<>Reksadana uang kos mama",Transaksi!$B$16:$B$5015,">="&DATE(Dashboard!$C$4,5,1),Transaksi!$B$16:$B$5015,"<="&EOMONTH(DATE(Dashboard!$C$4,5,1),0))-SUMIFS(Transaksi!$F$16:$F$5015,Transaksi!$G$16:$G$5015,"Tabungan",Transaksi!$D$16:$D$5015,"Masuk",Transaksi!$H$16:$H$5015,"<>Reksadana uang kos mama",Transaksi!$B$16:$B$5015,">="&DATE(Dashboard!$C$4,5,1),Transaksi!$B$16:$B$5015,"<="&EOMONTH(DATE(Dashboard!$C$4,5,1),0))) | F34: =C34-D34-E34 | G34: =SUMIFS(Transaksi!$F$16:$F$5015,Transaksi!$G$16:$G$5015,"Pendapatan",Transaksi!$B$16:$B$5015,">="&DATE(Dashboard!$C$4,5,1),Transaksi!$B$16:$B$5015,"<="&EOMONTH(DATE(Dashboard!$C$4,5,1),0),Transaksi!$H$16:$H$5015,"Uang Kos Mama")+SUMIFS(Transaksi!$F$16:$F$5015,Transaksi!$G$16:$G$5015,"Pendapatan",Transaksi!$B$16:$B$5015,">="&DATE(Dashboard!$C$4,5,1),Transaksi!$B$16:$B$5015,"<="&EOMONTH(DATE(Dashboard!$C$4,5,1),0),Transaksi!$H$16:$H$5015,"Uang Kedai")-SUMIFS(Transaksi!$F$16:$F$5015,Transaksi!$G$16:$G$5015,"Pengeluaran",Transaksi!$B$16:$B$5015,">="&DATE(Dashboard!$C$4,5,1),Transaksi!$B$16:$B$5015,"<="&EOMONTH(DATE(Dashboard!$C$4,5,1),0),Transaksi!$H$16:$H$5015,"Pengeluaran Uang Kos")-SUMIFS(Transaksi!$F$16:$F$5015,Transaksi!$G$16:$G$5015,"Pengeluaran",Transaksi!$B$16:$B$5015,">="&DATE(Dashboard!$C$4,5,1),Transaksi!$B$16:$B$5015,"<="&EOMONTH(DATE(Dashboard!$C$4,5,1),0),Transaksi!$H$16:$H$5015,"Pengeluaran Uang Kedai")-(SUMIFS(Transaksi!$F$16:$F$5015,Transaksi!$G$16:$G$5015,"Tabungan",Transaksi!$D$16:$D$5015,"Keluar",Transaksi!$H$16:$H$5015,"Reksadana uang kos mama",Transaksi!$B$16:$B$5015,">="&DATE(Dashboard!$C$4,5,1),Transaksi!$B$16:$B$5015,"<="&EOMONTH(DATE(Dashboard!$C$4,5,1),0))-SUMIFS(Transaksi!$F$16:$F$5015,Transaksi!$G$16:$G$5015,"Tabungan",Transaksi!$D$16:$D$5015,"Masuk",Transaksi!$H$16:$H$5015,"Reksadana uang kos mama",Transaksi!$B$16:$B$5015,">="&DATE(Dashboard!$C$4,5,1),Transaksi!$B$16:$B$5015,"<="&EOMONTH(DATE(Dashboard!$C$4,5,1),0))) | H34: =IF(DATE(Dashboard!$C$4,5,1)>TODAY(),"",SUMPRODUCT((Akun!$A$5:$A$104<>"")*1,Akun!$C$5:$C$104,--(Akun!$D$5:$D$104<=EOMONTH(DATE(Dashboard!$C$4,5,1),0)))+SUMIFS(Transaksi!$F$16:$F$5015,Transaksi!$D$16:$D$5015,"Masuk",Transaksi!$B$16:$B$5015,"<="&EOMONTH(DATE(Dashboard!$C$4,5,1),0))-SUMIFS(Transaksi!$F$16:$F$5015,Transaksi!$D$16:$D$5015,"Keluar",Transaksi!$B$16:$B$5015,"<="&EOMONTH(DATE(Dashboard!$C$4,5,1),0)))
B35: Juni | C35: =SUMIFS(Transaksi!$F$16:$F$5015,Transaksi!$G$16:$G$5015,"Pendapatan",Transaksi!$B$16:$B$5015,">="&DATE(Dashboard!$C$4,6,1),Transaksi!$B$16:$B$5015,"<="&EOMONTH(DATE(Dashboard!$C$4,6,1),0)) | D35: =SUMIFS(Transaksi!$F$16:$F$5015,Transaksi!$G$16:$G$5015,"Pengeluaran",Transaksi!$B$16:$B$5015,">="&DATE(Dashboard!$C$4,6,1),Transaksi!$B$16:$B$5015,"<="&EOMONTH(DATE(Dashboard!$C$4,6,1),0)) | E35: =(SUMIFS(Transaksi!$F$16:$F$5015,Transaksi!$G$16:$G$5015,"Tabungan",Transaksi!$D$16:$D$5015,"Keluar",Transaksi!$H$16:$H$5015,"<>Reksadana uang kos mama",Transaksi!$B$16:$B$5015,">="&DATE(Dashboard!$C$4,6,1),Transaksi!$B$16:$B$5015,"<="&EOMONTH(DATE(Dashboard!$C$4,6,1),0))-SUMIFS(Transaksi!$F$16:$F$5015,Transaksi!$G$16:$G$5015,"Tabungan",Transaksi!$D$16:$D$5015,"Masuk",Transaksi!$H$16:$H$5015,"<>Reksadana uang kos mama",Transaksi!$B$16:$B$5015,">="&DATE(Dashboard!$C$4,6,1),Transaksi!$B$16:$B$5015,"<="&EOMONTH(DATE(Dashboard!$C$4,6,1),0))) | F35: =C35-D35-E35 | G35: =SUMIFS(Transaksi!$F$16:$F$5015,Transaksi!$G$16:$G$5015,"Pendapatan",Transaksi!$B$16:$B$5015,">="&DATE(Dashboard!$C$4,6,1),Transaksi!$B$16:$B$5015,"<="&EOMONTH(DATE(Dashboard!$C$4,6,1),0),Transaksi!$H$16:$H$5015,"Uang Kos Mama")+SUMIFS(Transaksi!$F$16:$F$5015,Transaksi!$G$16:$G$5015,"Pendapatan",Transaksi!$B$16:$B$5015,">="&DATE(Dashboard!$C$4,6,1),Transaksi!$B$16:$B$5015,"<="&EOMONTH(DATE(Dashboard!$C$4,6,1),0),Transaksi!$H$16:$H$5015,"Uang Kedai")-SUMIFS(Transaksi!$F$16:$F$5015,Transaksi!$G$16:$G$5015,"Pengeluaran",Transaksi!$B$16:$B$5015,">="&DATE(Dashboard!$C$4,6,1),Transaksi!$B$16:$B$5015,"<="&EOMONTH(DATE(Dashboard!$C$4,6,1),0),Transaksi!$H$16:$H$5015,"Pengeluaran Uang Kos")-SUMIFS(Transaksi!$F$16:$F$5015,Transaksi!$G$16:$G$5015,"Pengeluaran",Transaksi!$B$16:$B$5015,">="&DATE(Dashboard!$C$4,6,1),Transaksi!$B$16:$B$5015,"<="&EOMONTH(DATE(Dashboard!$C$4,6,1),0),Transaksi!$H$16:$H$5015,"Pengeluaran Uang Kedai")-(SUMIFS(Transaksi!$F$16:$F$5015,Transaksi!$G$16:$G$5015,"Tabungan",Transaksi!$D$16:$D$5015,"Keluar",Transaksi!$H$16:$H$5015,"Reksadana uang kos mama",Transaksi!$B$16:$B$5015,">="&DATE(Dashboard!$C$4,6,1),Transaksi!$B$16:$B$5015,"<="&EOMONTH(DATE(Dashboard!$C$4,6,1),0))-SUMIFS(Transaksi!$F$16:$F$5015,Transaksi!$G$16:$G$5015,"Tabungan",Transaksi!$D$16:$D$5015,"Masuk",Transaksi!$H$16:$H$5015,"Reksadana uang kos mama",Transaksi!$B$16:$B$5015,">="&DATE(Dashboard!$C$4,6,1),Transaksi!$B$16:$B$5015,"<="&EOMONTH(DATE(Dashboard!$C$4,6,1),0))) | H35: =IF(DATE(Dashboard!$C$4,6,1)>TODAY(),"",SUMPRODUCT((Akun!$A$5:$A$104<>"")*1,Akun!$C$5:$C$104,--(Akun!$D$5:$D$104<=EOMONTH(DATE(Dashboard!$C$4,6,1),0)))+SUMIFS(Transaksi!$F$16:$F$5015,Transaksi!$D$16:$D$5015,"Masuk",Transaksi!$B$16:$B$5015,"<="&EOMONTH(DATE(Dashboard!$C$4,6,1),0))-SUMIFS(Transaksi!$F$16:$F$5015,Transaksi!$D$16:$D$5015,"Keluar",Transaksi!$B$16:$B$5015,"<="&EOMONTH(DATE(Dashboard!$C$4,6,1),0)))
B36: Juli | C36: =SUMIFS(Transaksi!$F$16:$F$5015,Transaksi!$G$16:$G$5015,"Pendapatan",Transaksi!$B$16:$B$5015,">="&DATE(Dashboard!$C$4,7,1),Transaksi!$B$16:$B$5015,"<="&EOMONTH(DATE(Dashboard!$C$4,7,1),0)) | D36: =SUMIFS(Transaksi!$F$16:$F$5015,Transaksi!$G$16:$G$5015,"Pengeluaran",Transaksi!$B$16:$B$5015,">="&DATE(Dashboard!$C$4,7,1),Transaksi!$B$16:$B$5015,"<="&EOMONTH(DATE(Dashboard!$C$4,7,1),0)) | E36: =(SUMIFS(Transaksi!$F$16:$F$5015,Transaksi!$G$16:$G$5015,"Tabungan",Transaksi!$D$16:$D$5015,"Keluar",Transaksi!$H$16:$H$5015,"<>Reksadana uang kos mama",Transaksi!$B$16:$B$5015,">="&DATE(Dashboard!$C$4,7,1),Transaksi!$B$16:$B$5015,"<="&EOMONTH(DATE(Dashboard!$C$4,7,1),0))-SUMIFS(Transaksi!$F$16:$F$5015,Transaksi!$G$16:$G$5015,"Tabungan",Transaksi!$D$16:$D$5015,"Masuk",Transaksi!$H$16:$H$5015,"<>Reksadana uang kos mama",Transaksi!$B$16:$B$5015,">="&DATE(Dashboard!$C$4,7,1),Transaksi!$B$16:$B$5015,"<="&EOMONTH(DATE(Dashboard!$C$4,7,1),0))) | F36: =C36-D36-E36 | G36: =SUMIFS(Transaksi!$F$16:$F$5015,Transaksi!$G$16:$G$5015,"Pendapatan",Transaksi!$B$16:$B$5015,">="&DATE(Dashboard!$C$4,7,1),Transaksi!$B$16:$B$5015,"<="&EOMONTH(DATE(Dashboard!$C$4,7,1),0),Transaksi!$H$16:$H$5015,"Uang Kos Mama")+SUMIFS(Transaksi!$F$16:$F$5015,Transaksi!$G$16:$G$5015,"Pendapatan",Transaksi!$B$16:$B$5015,">="&DATE(Dashboard!$C$4,7,1),Transaksi!$B$16:$B$5015,"<="&EOMONTH(DATE(Dashboard!$C$4,7,1),0),Transaksi!$H$16:$H$5015,"Uang Kedai")-SUMIFS(Transaksi!$F$16:$F$5015,Transaksi!$G$16:$G$5015,"Pengeluaran",Transaksi!$B$16:$B$5015,">="&DATE(Dashboard!$C$4,7,1),Transaksi!$B$16:$B$5015,"<="&EOMONTH(DATE(Dashboard!$C$4,7,1),0),Transaksi!$H$16:$H$5015,"Pengeluaran Uang Kos")-SUMIFS(Transaksi!$F$16:$F$5015,Transaksi!$G$16:$G$5015,"Pengeluaran",Transaksi!$B$16:$B$5015,">="&DATE(Dashboard!$C$4,7,1),Transaksi!$B$16:$B$5015,"<="&EOMONTH(DATE(Dashboard!$C$4,7,1),0),Transaksi!$H$16:$H$5015,"Pengeluaran Uang Kedai")-(SUMIFS(Transaksi!$F$16:$F$5015,Transaksi!$G$16:$G$5015,"Tabungan",Transaksi!$D$16:$D$5015,"Keluar",Transaksi!$H$16:$H$5015,"Reksadana uang kos mama",Transaksi!$B$16:$B$5015,">="&DATE(Dashboard!$C$4,7,1),Transaksi!$B$16:$B$5015,"<="&EOMONTH(DATE(Dashboard!$C$4,7,1),0))-SUMIFS(Transaksi!$F$16:$F$5015,Transaksi!$G$16:$G$5015,"Tabungan",Transaksi!$D$16:$D$5015,"Masuk",Transaksi!$H$16:$H$5015,"Reksadana uang kos mama",Transaksi!$B$16:$B$5015,">="&DATE(Dashboard!$C$4,7,1),Transaksi!$B$16:$B$5015,"<="&EOMONTH(DATE(Dashboard!$C$4,7,1),0))) | H36: =IF(DATE(Dashboard!$C$4,7,1)>TODAY(),"",SUMPRODUCT((Akun!$A$5:$A$104<>"")*1,Akun!$C$5:$C$104,--(Akun!$D$5:$D$104<=EOMONTH(DATE(Dashboard!$C$4,7,1),0)))+SUMIFS(Transaksi!$F$16:$F$5015,Transaksi!$D$16:$D$5015,"Masuk",Transaksi!$B$16:$B$5015,"<="&EOMONTH(DATE(Dashboard!$C$4,7,1),0))-SUMIFS(Transaksi!$F$16:$F$5015,Transaksi!$D$16:$D$5015,"Keluar",Transaksi!$B$16:$B$5015,"<="&EOMONTH(DATE(Dashboard!$C$4,7,1),0)))
B37: Agustus | C37: =SUMIFS(Transaksi!$F$16:$F$5015,Transaksi!$G$16:$G$5015,"Pendapatan",Transaksi!$B$16:$B$5015,">="&DATE(Dashboard!$C$4,8,1),Transaksi!$B$16:$B$5015,"<="&EOMONTH(DATE(Dashboard!$C$4,8,1),0)) | D37: =SUMIFS(Transaksi!$F$16:$F$5015,Transaksi!$G$16:$G$5015,"Pengeluaran",Transaksi!$B$16:$B$5015,">="&DATE(Dashboard!$C$4,8,1),Transaksi!$B$16:$B$5015,"<="&EOMONTH(DATE(Dashboard!$C$4,8,1),0)) | E37: =(SUMIFS(Transaksi!$F$16:$F$5015,Transaksi!$G$16:$G$5015,"Tabungan",Transaksi!$D$16:$D$5015,"Keluar",Transaksi!$H$16:$H$5015,"<>Reksadana uang kos mama",Transaksi!$B$16:$B$5015,">="&DATE(Dashboard!$C$4,8,1),Transaksi!$B$16:$B$5015,"<="&EOMONTH(DATE(Dashboard!$C$4,8,1),0))-SUMIFS(Transaksi!$F$16:$F$5015,Transaksi!$G$16:$G$5015,"Tabungan",Transaksi!$D$16:$D$5015,"Masuk",Transaksi!$H$16:$H$5015,"<>Reksadana uang kos mama",Transaksi!$B$16:$B$5015,">="&DATE(Dashboard!$C$4,8,1),Transaksi!$B$16:$B$5015,"<="&EOMONTH(DATE(Dashboard!$C$4,8,1),0))) | F37: =C37-D37-E37 | G37: =SUMIFS(Transaksi!$F$16:$F$5015,Transaksi!$G$16:$G$5015,"Pendapatan",Transaksi!$B$16:$B$5015,">="&DATE(Dashboard!$C$4,8,1),Transaksi!$B$16:$B$5015,"<="&EOMONTH(DATE(Dashboard!$C$4,8,1),0),Transaksi!$H$16:$H$5015,"Uang Kos Mama")+SUMIFS(Transaksi!$F$16:$F$5015,Transaksi!$G$16:$G$5015,"Pendapatan",Transaksi!$B$16:$B$5015,">="&DATE(Dashboard!$C$4,8,1),Transaksi!$B$16:$B$5015,"<="&EOMONTH(DATE(Dashboard!$C$4,8,1),0),Transaksi!$H$16:$H$5015,"Uang Kedai")-SUMIFS(Transaksi!$F$16:$F$5015,Transaksi!$G$16:$G$5015,"Pengeluaran",Transaksi!$B$16:$B$5015,">="&DATE(Dashboard!$C$4,8,1),Transaksi!$B$16:$B$5015,"<="&EOMONTH(DATE(Dashboard!$C$4,8,1),0),Transaksi!$H$16:$H$5015,"Pengeluaran Uang Kos")-SUMIFS(Transaksi!$F$16:$F$5015,Transaksi!$G$16:$G$5015,"Pengeluaran",Transaksi!$B$16:$B$5015,">="&DATE(Dashboard!$C$4,8,1),Transaksi!$B$16:$B$5015,"<="&EOMONTH(DATE(Dashboard!$C$4,8,1),0),Transaksi!$H$16:$H$5015,"Pengeluaran Uang Kedai")-(SUMIFS(Transaksi!$F$16:$F$5015,Transaksi!$G$16:$G$5015,"Tabungan",Transaksi!$D$16:$D$5015,"Keluar",Transaksi!$H$16:$H$5015,"Reksadana uang kos mama",Transaksi!$B$16:$B$5015,">="&DATE(Dashboard!$C$4,8,1),Transaksi!$B$16:$B$5015,"<="&EOMONTH(DATE(Dashboard!$C$4,8,1),0))-SUMIFS(Transaksi!$F$16:$F$5015,Transaksi!$G$16:$G$5015,"Tabungan",Transaksi!$D$16:$D$5015,"Masuk",Transaksi!$H$16:$H$5015,"Reksadana uang kos mama",Transaksi!$B$16:$B$5015,">="&DATE(Dashboard!$C$4,8,1),Transaksi!$B$16:$B$5015,"<="&EOMONTH(DATE(Dashboard!$C$4,8,1),0))) | H37: =IF(DATE(Dashboard!$C$4,8,1)>TODAY(),"",SUMPRODUCT((Akun!$A$5:$A$104<>"")*1,Akun!$C$5:$C$104,--(Akun!$D$5:$D$104<=EOMONTH(DATE(Dashboard!$C$4,8,1),0)))+SUMIFS(Transaksi!$F$16:$F$5015,Transaksi!$D$16:$D$5015,"Masuk",Transaksi!$B$16:$B$5015,"<="&EOMONTH(DATE(Dashboard!$C$4,8,1),0))-SUMIFS(Transaksi!$F$16:$F$5015,Transaksi!$D$16:$D$5015,"Keluar",Transaksi!$B$16:$B$5015,"<="&EOMONTH(DATE(Dashboard!$C$4,8,1),0)))
B38: September | C38: =SUMIFS(Transaksi!$F$16:$F$5015,Transaksi!$G$16:$G$5015,"Pendapatan",Transaksi!$B$16:$B$5015,">="&DATE(Dashboard!$C$4,9,1),Transaksi!$B$16:$B$5015,"<="&EOMONTH(DATE(Dashboard!$C$4,9,1),0)) | D38: =SUMIFS(Transaksi!$F$16:$F$5015,Transaksi!$G$16:$G$5015,"Pengeluaran",Transaksi!$B$16:$B$5015,">="&DATE(Dashboard!$C$4,9,1),Transaksi!$B$16:$B$5015,"<="&EOMONTH(DATE(Dashboard!$C$4,9,1),0)) | E38: =(SUMIFS(Transaksi!$F$16:$F$5015,Transaksi!$G$16:$G$5015,"Tabungan",Transaksi!$D$16:$D$5015,"Keluar",Transaksi!$H$16:$H$5015,"<>Reksadana uang kos mama",Transaksi!$B$16:$B$5015,">="&DATE(Dashboard!$C$4,9,1),Transaksi!$B$16:$B$5015,"<="&EOMONTH(DATE(Dashboard!$C$4,9,1),0))-SUMIFS(Transaksi!$F$16:$F$5015,Transaksi!$G$16:$G$5015,"Tabungan",Transaksi!$D$16:$D$5015,"Masuk",Transaksi!$H$16:$H$5015,"<>Reksadana uang kos mama",Transaksi!$B$16:$B$5015,">="&DATE(Dashboard!$C$4,9,1),Transaksi!$B$16:$B$5015,"<="&EOMONTH(DATE(Dashboard!$C$4,9,1),0))) | F38: =C38-D38-E38 | G38: =SUMIFS(Transaksi!$F$16:$F$5015,Transaksi!$G$16:$G$5015,"Pendapatan",Transaksi!$B$16:$B$5015,">="&DATE(Dashboard!$C$4,9,1),Transaksi!$B$16:$B$5015,"<="&EOMONTH(DATE(Dashboard!$C$4,9,1),0),Transaksi!$H$16:$H$5015,"Uang Kos Mama")+SUMIFS(Transaksi!$F$16:$F$5015,Transaksi!$G$16:$G$5015,"Pendapatan",Transaksi!$B$16:$B$5015,">="&DATE(Dashboard!$C$4,9,1),Transaksi!$B$16:$B$5015,"<="&EOMONTH(DATE(Dashboard!$C$4,9,1),0),Transaksi!$H$16:$H$5015,"Uang Kedai")-SUMIFS(Transaksi!$F$16:$F$5015,Transaksi!$G$16:$G$5015,"Pengeluaran",Transaksi!$B$16:$B$5015,">="&DATE(Dashboard!$C$4,9,1),Transaksi!$B$16:$B$5015,"<="&EOMONTH(DATE(Dashboard!$C$4,9,1),0),Transaksi!$H$16:$H$5015,"Pengeluaran Uang Kos")-SUMIFS(Transaksi!$F$16:$F$5015,Transaksi!$G$16:$G$5015,"Pengeluaran",Transaksi!$B$16:$B$5015,">="&DATE(Dashboard!$C$4,9,1),Transaksi!$B$16:$B$5015,"<="&EOMONTH(DATE(Dashboard!$C$4,9,1),0),Transaksi!$H$16:$H$5015,"Pengeluaran Uang Kedai")-(SUMIFS(Transaksi!$F$16:$F$5015,Transaksi!$G$16:$G$5015,"Tabungan",Transaksi!$D$16:$D$5015,"Keluar",Transaksi!$H$16:$H$5015,"Reksadana uang kos mama",Transaksi!$B$16:$B$5015,">="&DATE(Dashboard!$C$4,9,1),Transaksi!$B$16:$B$5015,"<="&EOMONTH(DATE(Dashboard!$C$4,9,1),0))-SUMIFS(Transaksi!$F$16:$F$5015,Transaksi!$G$16:$G$5015,"Tabungan",Transaksi!$D$16:$D$5015,"Masuk",Transaksi!$H$16:$H$5015,"Reksadana uang kos mama",Transaksi!$B$16:$B$5015,">="&DATE(Dashboard!$C$4,9,1),Transaksi!$B$16:$B$5015,"<="&EOMONTH(DATE(Dashboard!$C$4,9,1),0))) | H38: =IF(DATE(Dashboard!$C$4,9,1)>TODAY(),"",SUMPRODUCT((Akun!$A$5:$A$104<>"")*1,Akun!$C$5:$C$104,--(Akun!$D$5:$D$104<=EOMONTH(DATE(Dashboard!$C$4,9,1),0)))+SUMIFS(Transaksi!$F$16:$F$5015,Transaksi!$D$16:$D$5015,"Masuk",Transaksi!$B$16:$B$5015,"<="&EOMONTH(DATE(Dashboard!$C$4,9,1),0))-SUMIFS(Transaksi!$F$16:$F$5015,Transaksi!$D$16:$D$5015,"Keluar",Transaksi!$B$16:$B$5015,"<="&EOMONTH(DATE(Dashboard!$C$4,9,1),0)))
B39: Oktober | C39: =SUMIFS(Transaksi!$F$16:$F$5015,Transaksi!$G$16:$G$5015,"Pendapatan",Transaksi!$B$16:$B$5015,">="&DATE(Dashboard!$C$4,10,1),Transaksi!$B$16:$B$5015,"<="&EOMONTH(DATE(Dashboard!$C$4,10,1),0)) | D39: =SUMIFS(Transaksi!$F$16:$F$5015,Transaksi!$G$16:$G$5015,"Pengeluaran",Transaksi!$B$16:$B$5015,">="&DATE(Dashboard!$C$4,10,1),Transaksi!$B$16:$B$5015,"<="&EOMONTH(DATE(Dashboard!$C$4,10,1),0)) | E39: =(SUMIFS(Transaksi!$F$16:$F$5015,Transaksi!$G$16:$G$5015,"Tabungan",Transaksi!$D$16:$D$5015,"Keluar",Transaksi!$H$16:$H$5015,"<>Reksadana uang kos mama",Transaksi!$B$16:$B$5015,">="&DATE(Dashboard!$C$4,10,1),Transaksi!$B$16:$B$5015,"<="&EOMONTH(DATE(Dashboard!$C$4,10,1),0))-SUMIFS(Transaksi!$F$16:$F$5015,Transaksi!$G$16:$G$5015,"Tabungan",Transaksi!$D$16:$D$5015,"Masuk",Transaksi!$H$16:$H$5015,"<>Reksadana uang kos mama",Transaksi!$B$16:$B$5015,">="&DATE(Dashboard!$C$4,10,1),Transaksi!$B$16:$B$5015,"<="&EOMONTH(DATE(Dashboard!$C$4,10,1),0))) | F39: =C39-D39-E39 | G39: =SUMIFS(Transaksi!$F$16:$F$5015,Transaksi!$G$16:$G$5015,"Pendapatan",Transaksi!$B$16:$B$5015,">="&DATE(Dashboard!$C$4,10,1),Transaksi!$B$16:$B$5015,"<="&EOMONTH(DATE(Dashboard!$C$4,10,1),0),Transaksi!$H$16:$H$5015,"Uang Kos Mama")+SUMIFS(Transaksi!$F$16:$F$5015,Transaksi!$G$16:$G$5015,"Pendapatan",Transaksi!$B$16:$B$5015,">="&DATE(Dashboard!$C$4,10,1),Transaksi!$B$16:$B$5015,"<="&EOMONTH(DATE(Dashboard!$C$4,10,1),0),Transaksi!$H$16:$H$5015,"Uang Kedai")-SUMIFS(Transaksi!$F$16:$F$5015,Transaksi!$G$16:$G$5015,"Pengeluaran",Transaksi!$B$16:$B$5015,">="&DATE(Dashboard!$C$4,10,1),Transaksi!$B$16:$B$5015,"<="&EOMONTH(DATE(Dashboard!$C$4,10,1),0),Transaksi!$H$16:$H$5015,"Pengeluaran Uang Kos")-SUMIFS(Transaksi!$F$16:$F$5015,Transaksi!$G$16:$G$5015,"Pengeluaran",Transaksi!$B$16:$B$5015,">="&DATE(Dashboard!$C$4,10,1),Transaksi!$B$16:$B$5015,"<="&EOMONTH(DATE(Dashboard!$C$4,10,1),0),Transaksi!$H$16:$H$5015,"Pengeluaran Uang Kedai")-(SUMIFS(Transaksi!$F$16:$F$5015,Transaksi!$G$16:$G$5015,"Tabungan",Transaksi!$D$16:$D$5015,"Keluar",Transaksi!$H$16:$H$5015,"Reksadana uang kos mama",Transaksi!$B$16:$B$5015,">="&DATE(Dashboard!$C$4,10,1),Transaksi!$B$16:$B$5015,"<="&EOMONTH(DATE(Dashboard!$C$4,10,1),0))-SUMIFS(Transaksi!$F$16:$F$5015,Transaksi!$G$16:$G$5015,"Tabungan",Transaksi!$D$16:$D$5015,"Masuk",Transaksi!$H$16:$H$5015,"Reksadana uang kos mama",Transaksi!$B$16:$B$5015,">="&DATE(Dashboard!$C$4,10,1),Transaksi!$B$16:$B$5015,"<="&EOMONTH(DATE(Dashboard!$C$4,10,1),0))) | H39: =IF(DATE(Dashboard!$C$4,10,1)>TODAY(),"",SUMPRODUCT((Akun!$A$5:$A$104<>"")*1,Akun!$C$5:$C$104,--(Akun!$D$5:$D$104<=EOMONTH(DATE(Dashboard!$C$4,10,1),0)))+SUMIFS(Transaksi!$F$16:$F$5015,Transaksi!$D$16:$D$5015,"Masuk",Transaksi!$B$16:$B$5015,"<="&EOMONTH(DATE(Dashboard!$C$4,10,1),0))-SUMIFS(Transaksi!$F$16:$F$5015,Transaksi!$D$16:$D$5015,"Keluar",Transaksi!$B$16:$B$5015,"<="&EOMONTH(DATE(Dashboard!$C$4,10,1),0)))
B40: November | C40: =SUMIFS(Transaksi!$F$16:$F$5015,Transaksi!$G$16:$G$5015,"Pendapatan",Transaksi!$B$16:$B$5015,">="&DATE(Dashboard!$C$4,11,1),Transaksi!$B$16:$B$5015,"<="&EOMONTH(DATE(Dashboard!$C$4,11,1),0)) | D40: =SUMIFS(Transaksi!$F$16:$F$5015,Transaksi!$G$16:$G$5015,"Pengeluaran",Transaksi!$B$16:$B$5015,">="&DATE(Dashboard!$C$4,11,1),Transaksi!$B$16:$B$5015,"<="&EOMONTH(DATE(Dashboard!$C$4,11,1),0)) | E40: =(SUMIFS(Transaksi!$F$16:$F$5015,Transaksi!$G$16:$G$5015,"Tabungan",Transaksi!$D$16:$D$5015,"Keluar",Transaksi!$H$16:$H$5015,"<>Reksadana uang kos mama",Transaksi!$B$16:$B$5015,">="&DATE(Dashboard!$C$4,11,1),Transaksi!$B$16:$B$5015,"<="&EOMONTH(DATE(Dashboard!$C$4,11,1),0))-SUMIFS(Transaksi!$F$16:$F$5015,Transaksi!$G$16:$G$5015,"Tabungan",Transaksi!$D$16:$D$5015,"Masuk",Transaksi!$H$16:$H$5015,"<>Reksadana uang kos mama",Transaksi!$B$16:$B$5015,">="&DATE(Dashboard!$C$4,11,1),Transaksi!$B$16:$B$5015,"<="&EOMONTH(DATE(Dashboard!$C$4,11,1),0))) | F40: =C40-D40-E40 | G40: =SUMIFS(Transaksi!$F$16:$F$5015,Transaksi!$G$16:$G$5015,"Pendapatan",Transaksi!$B$16:$B$5015,">="&DATE(Dashboard!$C$4,11,1),Transaksi!$B$16:$B$5015,"<="&EOMONTH(DATE(Dashboard!$C$4,11,1),0),Transaksi!$H$16:$H$5015,"Uang Kos Mama")+SUMIFS(Transaksi!$F$16:$F$5015,Transaksi!$G$16:$G$5015,"Pendapatan",Transaksi!$B$16:$B$5015,">="&DATE(Dashboard!$C$4,11,1),Transaksi!$B$16:$B$5015,"<="&EOMONTH(DATE(Dashboard!$C$4,11,1),0),Transaksi!$H$16:$H$5015,"Uang Kedai")-SUMIFS(Transaksi!$F$16:$F$5015,Transaksi!$G$16:$G$5015,"Pengeluaran",Transaksi!$B$16:$B$5015,">="&DATE(Dashboard!$C$4,11,1),Transaksi!$B$16:$B$5015,"<="&EOMONTH(DATE(Dashboard!$C$4,11,1),0),Transaksi!$H$16:$H$5015,"Pengeluaran Uang Kos")-SUMIFS(Transaksi!$F$16:$F$5015,Transaksi!$G$16:$G$5015,"Pengeluaran",Transaksi!$B$16:$B$5015,">="&DATE(Dashboard!$C$4,11,1),Transaksi!$B$16:$B$5015,"<="&EOMONTH(DATE(Dashboard!$C$4,11,1),0),Transaksi!$H$16:$H$5015,"Pengeluaran Uang Kedai")-(SUMIFS(Transaksi!$F$16:$F$5015,Transaksi!$G$16:$G$5015,"Tabungan",Transaksi!$D$16:$D$5015,"Keluar",Transaksi!$H$16:$H$5015,"Reksadana uang kos mama",Transaksi!$B$16:$B$5015,">="&DATE(Dashboard!$C$4,11,1),Transaksi!$B$16:$B$5015,"<="&EOMONTH(DATE(Dashboard!$C$4,11,1),0))-SUMIFS(Transaksi!$F$16:$F$5015,Transaksi!$G$16:$G$5015,"Tabungan",Transaksi!$D$16:$D$5015,"Masuk",Transaksi!$H$16:$H$5015,"Reksadana uang kos mama",Transaksi!$B$16:$B$5015,">="&DATE(Dashboard!$C$4,11,1),Transaksi!$B$16:$B$5015,"<="&EOMONTH(DATE(Dashboard!$C$4,11,1),0))) | H40: =IF(DATE(Dashboard!$C$4,11,1)>TODAY(),"",SUMPRODUCT((Akun!$A$5:$A$104<>"")*1,Akun!$C$5:$C$104,--(Akun!$D$5:$D$104<=EOMONTH(DATE(Dashboard!$C$4,11,1),0)))+SUMIFS(Transaksi!$F$16:$F$5015,Transaksi!$D$16:$D$5015,"Masuk",Transaksi!$B$16:$B$5015,"<="&EOMONTH(DATE(Dashboard!$C$4,11,1),0))-SUMIFS(Transaksi!$F$16:$F$5015,Transaksi!$D$16:$D$5015,"Keluar",Transaksi!$B$16:$B$5015,"<="&EOMONTH(DATE(Dashboard!$C$4,11,1),0)))
B41: Desember | C41: =SUMIFS(Transaksi!$F$16:$F$5015,Transaksi!$G$16:$G$5015,"Pendapatan",Transaksi!$B$16:$B$5015,">="&DATE(Dashboard!$C$4,12,1),Transaksi!$B$16:$B$5015,"<="&EOMONTH(DATE(Dashboard!$C$4,12,1),0)) | D41: =SUMIFS(Transaksi!$F$16:$F$5015,Transaksi!$G$16:$G$5015,"Pengeluaran",Transaksi!$B$16:$B$5015,">="&DATE(Dashboard!$C$4,12,1),Transaksi!$B$16:$B$5015,"<="&EOMONTH(DATE(Dashboard!$C$4,12,1),0)) | E41: =(SUMIFS(Transaksi!$F$16:$F$5015,Transaksi!$G$16:$G$5015,"Tabungan",Transaksi!$D$16:$D$5015,"Keluar",Transaksi!$H$16:$H$5015,"<>Reksadana uang kos mama",Transaksi!$B$16:$B$5015,">="&DATE(Dashboard!$C$4,12,1),Transaksi!$B$16:$B$5015,"<="&EOMONTH(DATE(Dashboard!$C$4,12,1),0))-SUMIFS(Transaksi!$F$16:$F$5015,Transaksi!$G$16:$G$5015,"Tabungan",Transaksi!$D$16:$D$5015,"Masuk",Transaksi!$H$16:$H$5015,"<>Reksadana uang kos mama",Transaksi!$B$16:$B$5015,">="&DATE(Dashboard!$C$4,12,1),Transaksi!$B$16:$B$5015,"<="&EOMONTH(DATE(Dashboard!$C$4,12,1),0))) | F41: =C41-D41-E41 | G41: =SUMIFS(Transaksi!$F$16:$F$5015,Transaksi!$G$16:$G$5015,"Pendapatan",Transaksi!$B$16:$B$5015,">="&DATE(Dashboard!$C$4,12,1),Transaksi!$B$16:$B$5015,"<="&EOMONTH(DATE(Dashboard!$C$4,12,1),0),Transaksi!$H$16:$H$5015,"Uang Kos Mama")+SUMIFS(Transaksi!$F$16:$F$5015,Transaksi!$G$16:$G$5015,"Pendapatan",Transaksi!$B$16:$B$5015,">="&DATE(Dashboard!$C$4,12,1),Transaksi!$B$16:$B$5015,"<="&EOMONTH(DATE(Dashboard!$C$4,12,1),0),Transaksi!$H$16:$H$5015,"Uang Kedai")-SUMIFS(Transaksi!$F$16:$F$5015,Transaksi!$G$16:$G$5015,"Pengeluaran",Transaksi!$B$16:$B$5015,">="&DATE(Dashboard!$C$4,12,1),Transaksi!$B$16:$B$5015,"<="&EOMONTH(DATE(Dashboard!$C$4,12,1),0),Transaksi!$H$16:$H$5015,"Pengeluaran Uang Kos")-SUMIFS(Transaksi!$F$16:$F$5015,Transaksi!$G$16:$G$5015,"Pengeluaran",Transaksi!$B$16:$B$5015,">="&DATE(Dashboard!$C$4,12,1),Transaksi!$B$16:$B$5015,"<="&EOMONTH(DATE(Dashboard!$C$4,12,1),0),Transaksi!$H$16:$H$5015,"Pengeluaran Uang Kedai")-(SUMIFS(Transaksi!$F$16:$F$5015,Transaksi!$G$16:$G$5015,"Tabungan",Transaksi!$D$16:$D$5015,"Keluar",Transaksi!$H$16:$H$5015,"Reksadana uang kos mama",Transaksi!$B$16:$B$5015,">="&DATE(Dashboard!$C$4,12,1),Transaksi!$B$16:$B$5015,"<="&EOMONTH(DATE(Dashboard!$C$4,12,1),0))-SUMIFS(Transaksi!$F$16:$F$5015,Transaksi!$G$16:$G$5015,"Tabungan",Transaksi!$D$16:$D$5015,"Masuk",Transaksi!$H$16:$H$5015,"Reksadana uang kos mama",Transaksi!$B$16:$B$5015,">="&DATE(Dashboard!$C$4,12,1),Transaksi!$B$16:$B$5015,"<="&EOMONTH(DATE(Dashboard!$C$4,12,1),0))) | H41: =IF(DATE(Dashboard!$C$4,12,1)>TODAY(),"",SUMPRODUCT((Akun!$A$5:$A$104<>"")*1,Akun!$C$5:$C$104,--(Akun!$D$5:$D$104<=EOMONTH(DATE(Dashboard!$C$4,12,1),0)))+SUMIFS(Transaksi!$F$16:$F$5015,Transaksi!$D$16:$D$5015,"Masuk",Transaksi!$B$16:$B$5015,"<="&EOMONTH(DATE(Dashboard!$C$4,12,1),0))-SUMIFS(Transaksi!$F$16:$F$5015,Transaksi!$D$16:$D$5015,"Keluar",Transaksi!$B$16:$B$5015,"<="&EOMONTH(DATE(Dashboard!$C$4,12,1),0)))
B44: ="C. SALDO AKUN — AKHIR "&UPPER(C5)&" "&C4
B45: Akun | C45: Saldo | D45: Kelompok
B46: =Akun!A5 | C46: =IF(B46="","",(SUMIFS(Akun!$C$5:$C$104,Akun!$A$5:$A$104,B46,Akun!$D$5:$D$104,"<="&EOMONTH(DATE(Dashboard!$C$4,Dashboard!$D$4,1),0))+SUMIFS(Transaksi!$F$16:$F$5015,Transaksi!$C$16:$C$5015,B46,Transaksi!$D$16:$D$5015,"Masuk",Transaksi!$B$16:$B$5015,"<="&EOMONTH(DATE(Dashboard!$C$4,Dashboard!$D$4,1),0))-SUMIFS(Transaksi!$F$16:$F$5015,Transaksi!$C$16:$C$5015,B46,Transaksi!$D$16:$D$5015,"Keluar",Transaksi!$B$16:$B$5015,"<="&EOMONTH(DATE(Dashboard!$C$4,Dashboard!$D$4,1),0))-SUMIFS(Transaksi!$F$16:$F$5015,Transaksi!$C$16:$C$5015,B46,Transaksi!$D$16:$D$5015,"Pindah",Transaksi!$B$16:$B$5015,"<="&EOMONTH(DATE(Dashboard!$C$4,Dashboard!$D$4,1),0))+SUMIFS(Transaksi!$F$16:$F$5015,Transaksi!$E$16:$E$5015,B46,Transaksi!$D$16:$D$5015,"Pindah",Transaksi!$B$16:$B$5015,"<="&EOMONTH(DATE(Dashboard!$C$4,Dashboard!$D$4,1),0)))) | D46: =Akun!B5
B47: =Akun!A6 | C47: =IF(B47="","",(SUMIFS(Akun!$C$5:$C$104,Akun!$A$5:$A$104,B47,Akun!$D$5:$D$104,"<="&EOMONTH(DATE(Dashboard!$C$4,Dashboard!$D$4,1),0))+SUMIFS(Transaksi!$F$16:$F$5015,Transaksi!$C$16:$C$5015,B47,Transaksi!$D$16:$D$5015,"Masuk",Transaksi!$B$16:$B$5015,"<="&EOMONTH(DATE(Dashboard!$C$4,Dashboard!$D$4,1),0))-SUMIFS(Transaksi!$F$16:$F$5015,Transaksi!$C$16:$C$5015,B47,Transaksi!$D$16:$D$5015,"Keluar",Transaksi!$B$16:$B$5015,"<="&EOMONTH(DATE(Dashboard!$C$4,Dashboard!$D$4,1),0))-SUMIFS(Transaksi!$F$16:$F$5015,Transaksi!$C$16:$C$5015,B47,Transaksi!$D$16:$D$5015,"Pindah",Transaksi!$B$16:$B$5015,"<="&EOMONTH(DATE(Dashboard!$C$4,Dashboard!$D$4,1),0))+SUMIFS(Transaksi!$F$16:$F$5015,Transaksi!$E$16:$E$5015,B47,Transaksi!$D$16:$D$5015,"Pindah",Transaksi!$B$16:$B$5015,"<="&EOMONTH(DATE(Dashboard!$C$4,Dashboard!$D$4,1),0)))) | D47: =Akun!B6
...

Sheet Transaksi
A1: TRANSAKSI — CATAT, CARI & LACAK
A2: Cara pakai: isi sel kuning di kiri atas (boleh sebagian). Hasilnya langsung muncul: ringkasan di tengah, daftar poin transaksi yang cocok di kanan (kolom P–V, klik "Buka"). Data lengkap ada mulai baris 16 — bisa dilipat dengan tombol [–] di kiri.
P3: DAFTAR TRANSAKSI YANG COCOK | T3: ="Ditampilkan "&MIN(300,MAX($N$16:$N$5015))&" dari "&MAX($N$16:$N$5015)&" (terbaru dulu; persempit pencarian bila lebih dari 300)"
A4: Kata kunci | F4: RINGKASAN HASIL | P4: Tanggal | Q4: Akun | R4: Tipe | S4: Jumlah | T4: Tujuan › Sumber › Kategori | U4: Keterangan | V4: Buka
A5: Tujuan | C5: Semua | F5: Jumlah transaksi cocok | G5: =MAX(N16:N5015) | P5: =IF(1>MAX($N$16:$N$5015),"",INDEX($B$16:$B$5015,MATCH((MAX($N$16:$N$5015)-1+1),$N$16:$N$5015,0))) | Q5: =IF(1>MAX($N$16:$N$5015),"",INDEX($C$16:$C$5015,MATCH((MAX($N$16:$N$5015)-1+1),$N$16:$N$5015,0)))&IF(IF(1>MAX($N$16:$N$5015),"",INDEX($E$16:$E$5015,MATCH((MAX($N$16:$N$5015)-1+1),$N$16:$N$5015,0)))="",""," → "&IF(1>MAX($N$16:$N$5015),"",INDEX($E$16:$E$5015,MATCH((MAX($N$16:$N$5015)-1+1),$N$16:$N$5015,0)))) | R5: =IF(1>MAX($N$16:$N$5015),"",INDEX($D$16:$D$5015,MATCH((MAX($N$16:$N$5015)-1+1),$N$16:$N$5015,0))) | S5: =IF(1>MAX($N$16:$N$5015),"",INDEX($F$16:$F$5015,MATCH((MAX($N$16:$N$5015)-1+1),$N$16:$N$5015,0))) | T5: =IF(1>MAX($N$16:$N$5015),"",IF(1>MAX($N$16:$N$5015),"",INDEX($G$16:$G$5015,MATCH((MAX($N$16:$N$5015)-1+1),$N$16:$N$5015,0)))&" › "&IF(1>MAX($N$16:$N$5015),"",INDEX($H$16:$H$5015,MATCH((MAX($N$16:$N$5015)-1+1),$N$16:$N$5015,0)))&" › "&IF(1>MAX($N$16:$N$5015),"",INDEX($I$16:$I$5015,MATCH((MAX($N$16:$N$5015)-1+1),$N$16:$N$5015,0)))) | U5: =IF(1>MAX($N$16:$N$5015),"",INDEX($J$16:$J$5015,MATCH((MAX($N$16:$N$5015)-1+1),$N$16:$N$5015,0)))&IF(IF(1>MAX($N$16:$N$5015),"",INDEX($L$16:$L$5015,MATCH((MAX($N$16:$N$5015)-1+1),$N$16:$N$5015,0)))="",""," ["&IF(1>MAX($N$16:$N$5015),"",INDEX($L$16:$L$5015,MATCH((MAX($N$16:$N$5015)-1+1),$N$16:$N$5015,0)))&"]") | V5: =IF(1>MAX($N$16:$N$5015),"",HYPERLINK("#Transaksi!B"&(MATCH((MAX($N$16:$N$5015)-1+1),$N$16:$N$5015,0)+15),"Buka"))
A6: Sumber | C6: Semua | F6: Uang masuk | G6: =SUMIFS(F16:F5015,M16:M5015,"✓",D16:D5015,"Masuk") | P6: =IF(2>MAX($N$16:$N$5015),"",INDEX($B$16:$B$5015,MATCH((MAX($N$16:$N$5015)-2+1),$N$16:$N$5015,0))) | Q6: =IF(2>MAX($N$16:$N$5015),"",INDEX($C$16:$C$5015,MATCH((MAX($N$16:$N$5015)-2+1),$N$16:$N$5015,0)))&IF(IF(2>MAX($N$16:$N$5015),"",INDEX($E$16:$E$5015,MATCH((MAX($N$16:$N$5015)-2+1),$N$16:$N$5015,0)))="",""," → "&IF(2>MAX($N$16:$N$5015),"",INDEX($E$16:$E$5015,MATCH((MAX($N$16:$N$5015)-2+1),$N$16:$N$5015,0)))) | R6: =IF(2>MAX($N$16:$N$5015),"",INDEX($D$16:$D$5015,MATCH((MAX($N$16:$N$5015)-2+1),$N$16:$N$5015,0))) | S6: =IF(2>MAX($N$16:$N$5015),"",INDEX($F$16:$F$5015,MATCH((MAX($N$16:$N$5015)-2+1),$N$16:$N$5015,0))) | T6: =IF(2>MAX($N$16:$N$5015),"",IF(2>MAX($N$16:$N$5015),"",INDEX($G$16:$G$5015,MATCH((MAX($N$16:$N$5015)-2+1),$N$16:$N$5015,0)))&" › "&IF(2>MAX($N$16:$N$5015),"",INDEX($H$16:$H$5015,MATCH((MAX($N$16:$N$5015)-2+1),$N$16:$N$5015,0)))&" › "&IF(2>MAX($N$16:$N$5015),"",INDEX($I$16:$I$5015,MATCH((MAX($N$16:$N$5015)-2+1),$N$16:$N$5015,0)))) | U6: =IF(2>MAX($N$16:$N$5015),"",INDEX($J$16:$J$5015,MATCH((MAX($N$16:$N$5015)-2+1),$N$16:$N$5015,0)))&IF(IF(2>MAX($N$16:$N$5015),"",INDEX($L$16:$L$5015,MATCH((MAX($N$16:$N$5015)-2+1),$N$16:$N$5015,0)))="",""," ["&IF(2>MAX($N$16:$N$5015),"",INDEX($L$16:$L$5015,MATCH((MAX($N$16:$N$5015)-2+1),$N$16:$N$5015,0)))&"]") | V6: =IF(2>MAX($N$16:$N$5015),"",HYPERLINK("#Transaksi!B"&(MATCH((MAX($N$16:$N$5015)-2+1),$N$16:$N$5015,0)+15),"Buka"))
A7: Kategori | C7: Semua | F7: Uang keluar | G7: =SUMIFS(F16:F5015,M16:M5015,"✓",D16:D5015,"Keluar") | P7: =IF(3>MAX($N$16:$N$5015),"",INDEX($B$16:$B$5015,MATCH((MAX($N$16:$N$5015)-3+1),$N$16:$N$5015,0))) | Q7: =IF(3>MAX($N$16:$N$5015),"",INDEX($C$16:$C$5015,MATCH((MAX($N$16:$N$5015)-3+1),$N$16:$N$5015,0)))&IF(IF(3>MAX($N$16:$N$5015),"",INDEX($E$16:$E$5015,MATCH((MAX($N$16:$N$5015)-3+1),$N$16:$N$5015,0)))="",""," → "&IF(3>MAX($N$16:$N$5015),"",INDEX($E$16:$E$5015,MATCH((MAX($N$16:$N$5015)-3+1),$N$16:$N$5015,0)))) | R7: =IF(3>MAX($N$16:$N$5015),"",INDEX($D$16:$D$5015,MATCH((MAX($N$16:$N$5015)-3+1),$N$16:$N$5015,0))) | S7: =IF(3>MAX($N$16:$N$5015),"",INDEX($F$16:$F$5015,MATCH((MAX($N$16:$N$5015)-3+1),$N$16:$N$5015,0))) | T7: =IF(3>MAX($N$16:$N$5015),"",IF(3>MAX($N$16:$N$5015),"",INDEX($G$16:$G$5015,MATCH((MAX($N$16:$N$5015)-3+1),$N$16:$N$5015,0)))&" › "&IF(3>MAX($N$16:$N$5015),"",INDEX($H$16:$H$5015,MATCH((MAX($N$16:$N$5015)-3+1),$N$16:$N$5015,0)))&" › "&IF(3>MAX($N$16:$N$5015),"",INDEX($I$16:$I$5015,MATCH((MAX($N$16:$N$5015)-3+1),$N$16:$N$5015,0)))) | U7: =IF(3>MAX($N$16:$N$5015),"",INDEX($J$16:$J$5015,MATCH((MAX($N$16:$N$5015)-3+1),$N$16:$N$5015,0)))&IF(IF(3>MAX($N$16:$N$5015),"",INDEX($L$16:$L$5015,MATCH((MAX($N$16:$N$5015)-3+1),$N$16:$N$5015,0)))="",""," ["&IF(3>MAX($N$16:$N$5015),"",INDEX($L$16:$L$5015,MATCH((MAX($N$16:$N$5015)-3+1),$N$16:$N$5015,0)))&"]") | V7: =IF(3>MAX($N$16:$N$5015),"",HYPERLINK("#Transaksi!B"&(MATCH((MAX($N$16:$N$5015)-3+1),$N$16:$N$5015,0)+15),"Buka"))
A8: Akun | C8: Semua | F8: Pindah uang | G8: =SUMIFS(F16:F5015,M16:M5015,"✓",D16:D5015,"Pindah") | P8: =IF(4>MAX($N$16:$N$5015),"",INDEX($B$16:$B$5015,MATCH((MAX($N$16:$N$5015)-4+1),$N$16:$N$5015,0))) | Q8: =IF(4>MAX($N$16:$N$5015),"",INDEX($C$16:$C$5015,MATCH((MAX($N$16:$N$5015)-4+1),$N$16:$N$5015,0)))&IF(IF(4>MAX($N$16:$N$5015),"",INDEX($E$16:$E$5015,MATCH((MAX($N$16:$N$5015)-4+1),$N$16:$N$5015,0)))="",""," → "&IF(4>MAX($N$16:$N$5015),"",INDEX($E$16:$E$5015,MATCH((MAX($N$16:$N$5015)-4+1),$N$16:$N$5015,0)))) | R8: =IF(4>MAX($N$16:$N$5015),"",INDEX($D$16:$D$5015,MATCH((MAX($N$16:$N$5015)-4+1),$N$16:$N$5015,0))) | S8: =IF(4>MAX($N$16:$N$5015),"",INDEX($F$16:$F$5015,MATCH((MAX($N$16:$N$5015)-4+1),$N$16:$N$5015,0))) | T8: =IF(4>MAX($N$16:$N$5015),"",IF(4>MAX($N$16:$N$5015),"",INDEX($G$16:$G$5015,MATCH((MAX($N$16:$N$5015)-4+1),$N$16:$N$5015,0)))&" › "&IF(4>MAX($N$16:$N$5015),"",INDEX($H$16:$H$5015,MATCH((MAX($N$16:$N$5015)-4+1),$N$16:$N$5015,0)))&" › "&IF(4>MAX($N$16:$N$5015),"",INDEX($I$16:$I$5015,MATCH((MAX($N$16:$N$5015)-4+1),$N$16:$N$5015,0)))) | U8: =IF(4>MAX($N$16:$N$5015),"",INDEX($J$16:$J$5015,MATCH((MAX($N$16:$N$5015)-4+1),$N$16:$N$5015,0)))&IF(IF(4>MAX($N$16:$N$5015),"",INDEX($L$16:$L$5015,MATCH((MAX($N$16:$N$5015)-4+1),$N$16:$N$5015,0)))="",""," ["&IF(4>MAX($N$16:$N$5015),"",INDEX($L$16:$L$5015,MATCH((MAX($N$16:$N$5015)-4+1),$N$16:$N$5015,0)))&"]") | V8: =IF(4>MAX($N$16:$N$5015),"",HYPERLINK("#Transaksi!B"&(MATCH((MAX($N$16:$N$5015)-4+1),$N$16:$N$5015,0)+15),"Buka"))
A9: Tipe | C9: Semua | F9: Pendapatan | G9: =SUMIFS(F16:F5015,M16:M5015,"✓",G16:G5015,"Pendapatan") | P9: =IF(5>MAX($N$16:$N$5015),"",INDEX($B$16:$B$5015,MATCH((MAX($N$16:$N$5015)-5+1),$N$16:$N$5015,0))) | Q9: =IF(5>MAX($N$16:$N$5015),"",INDEX($C$16:$C$5015,MATCH((MAX($N$16:$N$5015)-5+1),$N$16:$N$5015,0)))&IF(IF(5>MAX($N$16:$N$5015),"",INDEX($E$16:$E$5015,MATCH((MAX($N$16:$N$5015)-5+1),$N$16:$N$5015,0)))="",""," → "&IF(5>MAX($N$16:$N$5015),"",INDEX($E$16:$E$5015,MATCH((MAX($N$16:$N$5015)-5+1),$N$16:$N$5015,0)))) | R9: =IF(5>MAX($N$16:$N$5015),"",INDEX($D$16:$D$5015,MATCH((MAX($N$16:$N$5015)-5+1),$N$16:$N$5015,0))) | S9: =IF(5>MAX($N$16:$N$5015),"",INDEX($F$16:$F$5015,MATCH((MAX($N$16:$N$5015)-5+1),$N$16:$N$5015,0))) | T9: =IF(5>MAX($N$16:$N$5015),"",IF(5>MAX($N$16:$N$5015),"",INDEX($G$16:$G$5015,MATCH((MAX($N$16:$N$5015)-5+1),$N$16:$N$5015,0)))&" › "&IF(5>MAX($N$16:$N$5015),"",INDEX($H$16:$H$5015,MATCH((MAX($N$16:$N$5015)-5+1),$N$16:$N$5015,0)))&" › "&IF(5>MAX($N$16:$N$5015),"",INDEX($I$16:$I$5015,MATCH((MAX($N$16:$N$5015)-5+1),$N$16:$N$5015,0)))) | U9: =IF(5>MAX($N$16:$N$5015),"",INDEX($J$16:$J$5015,MATCH((MAX($N$16:$N$5015)-5+1),$N$16:$N$5015,0)))&IF(IF(5>MAX($N$16:$N$5015),"",INDEX($L$16:$L$5015,MATCH((MAX($N$16:$N$5015)-5+1),$N$16:$N$5015,0)))="",""," ["&IF(5>MAX($N$16:$N$5015),"",INDEX($L$16:$L$5015,MATCH((MAX($N$16:$N$5015)-5+1),$N$16:$N$5015,0)))&"]") | V9: =IF(5>MAX($N$16:$N$5015),"",HYPERLINK("#Transaksi!B"&(MATCH((MAX($N$16:$N$5015)-5+1),$N$16:$N$5015,0)+15),"Buka"))
A10: Dari tanggal | F10: Pengeluaran | G10: =SUMIFS(F16:F5015,M16:M5015,"✓",G16:G5015,"Pengeluaran") | P10: =IF(6>MAX($N$16:$N$5015),"",INDEX($B$16:$B$5015,MATCH((MAX($N$16:$N$5015)-6+1),$N$16:$N$5015,0))) | Q10: =IF(6>MAX($N$16:$N$5015),"",INDEX($C$16:$C$5015,MATCH((MAX($N$16:$N$5015)-6+1),$N$16:$N$5015,0)))&IF(IF(6>MAX($N$16:$N$5015),"",INDEX($E$16:$E$5015,MATCH((MAX($N$16:$N$5015)-6+1),$N$16:$N$5015,0)))="",""," → "&IF(6>MAX($N$16:$N$5015),"",INDEX($E$16:$E$5015,MATCH((MAX($N$16:$N$5015)-6+1),$N$16:$N$5015,0)))) | R10: =IF(6>MAX($N$16:$N$5015),"",INDEX($D$16:$D$5015,MATCH((MAX($N$16:$N$5015)-6+1),$N$16:$N$5015,0))) | S10: =IF(6>MAX($N$16:$N$5015),"",INDEX($F$16:$F$5015,MATCH((MAX($N$16:$N$5015)-6+1),$N$16:$N$5015,0))) | T10: =IF(6>MAX($N$16:$N$5015),"",IF(6>MAX($N$16:$N$5015),"",INDEX($G$16:$G$5015,MATCH((MAX($N$16:$N$5015)-6+1),$N$16:$N$5015,0)))&" › "&IF(6>MAX($N$16:$N$5015),"",INDEX($H$16:$H$5015,MATCH((MAX($N$16:$N$5015)-6+1),$N$16:$N$5015,0)))&" › "&IF(6>MAX($N$16:$N$5015),"",INDEX($I$16:$I$5015,MATCH((MAX($N$16:$N$5015)-6+1),$N$16:$N$5015,0)))) | U10: =IF(6>MAX($N$16:$N$5015),"",INDEX($J$16:$J$5015,MATCH((MAX($N$16:$N$5015)-6+1),$N$16:$N$5015,0)))&IF(IF(6>MAX($N$16:$N$5015),"",INDEX($L$16:$L$5015,MATCH((MAX($N$16:$N$5015)-6+1),$N$16:$N$5015,0)))="",""," ["&IF(6>MAX($N$16:$N$5015),"",INDEX($L$16:$L$5015,MATCH((MAX($N$16:$N$5015)-6+1),$N$16:$N$5015,0)))&"]") | V10: =IF(6>MAX($N$16:$N$5015),"",HYPERLINK("#Transaksi!B"&(MATCH((MAX($N$16:$N$5015)-6+1),$N$16:$N$5015,0)+15),"Buka"))
A11: Sampai tanggal | F11: Saldo akun terpilih | G11: =IF(OR($C$8="",$C$8="Semua"),"pilih akun di C8",(SUMIFS(Akun!$C$5:$C$104,Akun!$A$5:$A$104,$C$8,Akun!$D$5:$D$104,"<="&IF($C$11="",TODAY(),$C$11))+SUMIFS(Transaksi!$F$16:$F$5015,Transaksi!$C$16:$C$5015,$C$8,Transaksi!$D$16:$D$5015,"Masuk",Transaksi!$B$16:$B$5015,"<="&IF($C$11="",TODAY(),$C$11))-SUMIFS(Transaksi!$F$16:$F$5015,Transaksi!$C$16:$C$5015,$C$8,Transaksi!$D$16:$D$5015,"Keluar",Transaksi!$B$16:$B$5015,"<="&IF($C$11="",TODAY(),$C$11))-SUMIFS(Transaksi!$F$16:$F$5015,Transaksi!$C$16:$C$5015,$C$8,Transaksi!$D$16:$D$5015,"Pindah",Transaksi!$B$16:$B$5015,"<="&IF($C$11="",TODAY(),$C$11))+SUMIFS(Transaksi!$F$16:$F$5015,Transaksi!$E$16:$E$5015,$C$8,Transaksi!$D$16:$D$5015,"Pindah",Transaksi!$B$16:$B$5015,"<="&IF($C$11="",TODAY(),$C$11)))) | P11: =IF(7>MAX($N$16:$N$5015),"",INDEX($B$16:$B$5015,MATCH((MAX($N$16:$N$5015)-7+1),$N$16:$N$5015,0))) | Q11: =IF(7>MAX($N$16:$N$5015),"",INDEX($C$16:$C$5015,MATCH((MAX($N$16:$N$5015)-7+1),$N$16:$N$5015,0)))&IF(IF(7>MAX($N$16:$N$5015),"",INDEX($E$16:$E$5015,MATCH((MAX($N$16:$N$5015)-7+1),$N$16:$N$5015,0)))="",""," → "&IF(7>MAX($N$16:$N$5015),"",INDEX($E$16:$E$5015,MATCH((MAX($N$16:$N$5015)-7+1),$N$16:$N$5015,0)))) | R11: =IF(7>MAX($N$16:$N$5015),"",INDEX($D$16:$D$5015,MATCH((MAX($N$16:$N$5015)-7+1),$N$16:$N$5015,0))) | S11: =IF(7>MAX($N$16:$N$5015),"",INDEX($F$16:$F$5015,MATCH((MAX($N$16:$N$5015)-7+1),$N$16:$N$5015,0))) | T11: =IF(7>MAX($N$16:$N$5015),"",IF(7>MAX($N$16:$N$5015),"",INDEX($G$16:$G$5015,MATCH((MAX($N$16:$N$5015)-7+1),$N$16:$N$5015,0)))&" › "&IF(7>MAX($N$16:$N$5015),"",INDEX($H$16:$H$5015,MATCH((MAX($N$16:$N$5015)-7+1),$N$16:$N$5015,0)))&" › "&IF(7>MAX($N$16:$N$5015),"",INDEX($I$16:$I$5015,MATCH((MAX($N$16:$N$5015)-7+1),$N$16:$N$5015,0)))) | U11: =IF(7>MAX($N$16:$N$5015),"",INDEX($J$16:$J$5015,MATCH((MAX($N$16:$N$5015)-7+1),$N$16:$N$5015,0)))&IF(IF(7>MAX($N$16:$N$5015),"",INDEX($L$16:$L$5015,MATCH((MAX($N$16:$N$5015)-7+1),$N$16:$N$5015,0)))="",""," ["&IF(7>MAX($N$16:$N$5015),"",INDEX($L$16:$L$5015,MATCH((MAX($N$16:$N$5015)-7+1),$N$16:$N$5015,0)))&"]") | V11: =IF(7>MAX($N$16:$N$5015),"",HYPERLINK("#Transaksi!B"&(MATCH((MAX($N$16:$N$5015)-7+1),$N$16:$N$5015,0)+15),"Buka"))
